Workbook

Sheet Előlap
A1: PR-10-43-03 | B1: Key machine output follow
A3: Folyamatgazda: | B3: Termelési csoport
A5: Folyamat | B5: R | C5: A | D5: C | E5: I | H5: A szabályzattal kapcsolatos személyek
A6: Management | C6: X | E6: X | H6: Készítette | I6: Borics Krisztián
A7: Quality | D7: X | E7: X | H7: Ellenőrizte | I7: László Tamás
A8: Production | B8: X | D8: X | E8: X | H8: Jóváhagyta és elrendelte | I8: Chiaki Hashiba
A9: Logistics | D9: X | E9: X | H9: Hatálybalépés dátuma | I9: 43116
A10: Sales | E10: X | H10: Változások
A11: Project Management | E11: X | H11: =I9 -> 43116 | I11: Első kiadás
A12: Human resources | D12: X | E12: X | H12: 43628 | I12: Kiegészítés : Üzemi kimentet időarányos követése, Átcsomagolós anyagok időarányos követése, Action Plan bevezetése.
A13: Engineering Support | E13: X

Sheet COIL inkjet_Laci
B1: QTY | C1: SH
A2: 1200-1347 | B2: 1 | C2: 1.26 | D2: =C2*B2 -> 1.26
A3: 1200-1368 | B3: 15 | C3: =1.05*3 -> 3.15 | D3: =C3*B3 -> 47.25
A4: 1201-1221 | B4: 31 | C4: 1.67 | D4: =C4*B4 -> 51.77
A5: 2000-0722 | B5: 0.326 | C5: 2.33 | D5: =C5*B5 -> 0.75958
A6: SZUM | D6: =SUM(D2:D5) -> 101.03958
D7: =2*17*8 -> 272 | E7: =D6/D7 -> 0.37146904

Sheet Headcount
A1: Head | F1: AVG Difference to the plan
A2: Count
B7: Workday | F7: 15 | Q7: Adott napi könyvelt üzemidő, USB, Visual, ContiVisual, Pack nélkül.
B8: Actual day | F8: 15 | L8: Állandó
A9: Day | B9: Netto HC plan | C9: Nettó létszámterv (kumulált) / Netto HC plan (cum) | D9: Brutto HC plan | E9: Other Work (PL. Support tape cleaning, Packaging) | F9: Daily Actual HC | G9: FFC Indirect | H9: QA Indirect | I9: FFC direct+indirect | J9: Aktuális Létszám (kumulatív) / Actual HC (cum) | K9: Daily Actual HC AVG | L9: Daily HC plan AVG | M9: Holiday | N9: Sick leave | O9: Difference | P9: Available Working hour (AWH) | Q9: Generate standard hour (GSH) Actual WK from BC) wihout packaging, conti, visual, usb (manual inspection csoport)
A10: 2 | B10: 20 | C10: =B10 -> 20 | D10: =B10*1.13 -> 22.6 | E10: 0 | F10: 17 | G10: 6 | H10: 5 | I10: =F10+G10 -> 23 | J10: =F10 -> 17 | K10: =J10 -> 17 | L10: 20 | M10: 0 | N10: 6 | O10: =IF(F10+E10="",0,F10-B10) -> -3 | P10: =B10*7.33 -> 146.6 | Q10: 149.56 | R10: =Q10/P10 -> 1.020191 | S10: =B10/F10 -> 1.1764706
A11: 3 | B11: 20 | C11: =C10+B11 -> 40 | D11: =B11*1.13 -> 22.6 | E11: 0 | F11: 16 | G11: 6 | H11: 5 | I11: =F11+G11 -> 22 | J11: =J10+F11 -> 33 | K11: =F11 -> 16 | L11: 20 | M11: 1 | N11: 6 | O11: =IF(F11+E11="",0,F11-B11) -> -4 | P11: =B11*7.33 -> 146.6 | Q11: 145.13 | R11: =Q11/P11 -> 0.98997271 | S11: =B11/F11 -> 1.25
A12: 4 | B12: 22 | C12: =C11+B12 -> 62 | D12: =B12*1.13 -> 24.86 | E12: 0 | F12: 17 | G12: 6 | H12: 5 | I12: =F12+G12 -> 23 | J12: =J11+F12 -> 50 | K12: =(K11+F12)/2 -> 16.5 | L12: 20 | M12: 0 | N12: 6 | O12: =IF(F12+E12="",0,F12-B12) -> -5 | P12: =B12*7.33 -> 161.26 | Q12: 158.49 | R12: =Q12/P12 -> 0.98282277 | S12: =B12/F12 -> 1.2941176
A13: 5 | B13: 22 | C13: =C12+B13 -> 84 | D13: =B13*1.13 -> 24.86 | E13: 0 | F13: 17 | G13: 6 | H13: 5 | I13: =F13+G13 -> 23 | J13: =J12+F13 -> 67 | K13: =(K12+F13)/2 -> 16.75 | L13: 20 | M13: 1 | N13: 5 | O13: =IF(F13+E13="",0,F13-B13) -> -5 | P13: =B13*7.33 -> 161.26 | Q13: 160.66 | R13: =Q13/P13 -> 0.9962793 | S13: =B13/F13 -> 1.2941176
A14: 6 | B14: 22 | C14: =C13+B14 -> 106 | D14: =B14*1.13 -> 24.86 | E14: 0 | F14: 15 | G14: 6 | H14: 6 | I14: =F14+G14 -> 21 | J14: =J13+F14 -> 82 | K14: =(K13+F14)/2 -> 15.875 | L14: 20 | M14: 2 | N14: 6 | O14: =IF(F14+E14="",0,F14-B14) -> -7 | P14: =B14*7.33 -> 161.26 | Q14: 150.16 | R14: =Q14/P14 -> 0.93116706 | S14: =B14/F14 -> 1.4666667
A15: 9 | B15: 23 | C15: =C14+B15 -> 129 | D15: =B15*1.13 -> 25.99 | E15: 0 | F15: 19 | G15: 6 | H15: 6 | I15: =F15+G15 -> 25 | J15: =J14+F15 -> 101 | K15: =(K14+F15)/2 -> 17.4375 | L15: 20 | M15: 0 | N15: 4 | O15: =IF(F15+E15="",0,F15-B15) -> -4 | P15: =B15*6 -> 138 | Q15: 170.92 | R15: =Q15/P15 -> 1.2385507 | S15: =B15/F15 -> 1.2105263
A16: 10 | B16: 22 | C16: =C15+B16 -> 151 | D16: =B16*1.13 -> 24.86 | E16: 0 | F16: 19 | G16: 6 | H16: 6 | I16: =F16+G16 -> 25 | J16: =J15+F16 -> 120 | K16: =(K15+F16)/2 -> 18.21875 | L16: 20 | M16: 0 | N16: 4 | O16: =IF(F16+E16="",0,F16-B16) -> -3 | P16: =B16*7.33 -> 161.26 | Q16: 177.26 | R16: =Q16/P16 -> 1.0992187 | S16: =B16/F16 -> 1.1578947
A17: 11 | B17: 23 | C17: =C16+B17 -> 174 | D17: =B17*1.13 -> 25.99 | E17: 0 | F17: 18 | G17: 6 | H17: 9 | I17: =F17+G17 -> 24 | J17: =J16+F17 -> 138 | K17: =(K16+F17)/2 -> 18.109375 | L17: 20 | M17: 1 | N17: 4 | O17: =IF(F17+E17="",0,F17-B17) -> -5 | P17: =B17*7.33 -> 168.59 | Q17: 157.46 | R17: =Q17/P17 -> 0.93398185 | S17: =B17/F17 -> 1.2777778
A18: 12 | B18: 24 | C18: =C17+B18 -> 198 | D18: =B18*1.13 -> 27.12 | E18: 0 | F18: 19 | G18: 6 | H18: 9 | I18: =F18+G18 -> 25 | J18: =J17+F18 -> 157 | K18: =(K17+F18)/2 -> 18.554688 | L18: 20 | M18: 0 | N18: 3 | O18: =IF(F18+E18="",0,F18-B18) -> -5 | P18: =B18*7.33 -> 175.92 | Q18: 149.98 | R18: =Q18/P18 -> 0.85254661 | S18: =B18/F18 -> 1.2631579
A19: 13 | B19: 23 | C19: =C18+B19 -> 221 | D19: =B19*1.13 -> 25.99 | E19: 0 | F19: 11 | G19: 5 | H19: 16 | I19: =F19+G19 -> 16 | J19: =J18+F19 -> 168 | K19: =(K18+F19)/2 -> 14.777344 | L19: 20 | M19: 1 | N19: 3 | O19: =IF(F19+E19="",0,F19-B19) -> -12 | P19: =B19*7.33 -> 168.59 | Q19: 115.46 | R19: =Q19/P19 -> 0.68485675 | S19: =B19/F19 -> 2.0909091
A20: 16 | B20: 20 | C20: =C19+B20 -> 241 | D20: =B20*1.13 -> 22.6 | E20: 0 | F20: 11 | G20: 6 | H20: 16 | I20: =F20+G20 -> 17 | J20: =J19+F20 -> 179 | K20: =(K19+F20)/2 -> 12.888672 | L20: 20 | M20: 0 | N20: 4 | O20: =IF(F20+E20="",0,F20-B20) -> -9 | P20: =B20*7.33 -> 146.6 | Q20: 106.49 | R20: =Q20/P20 -> 0.72639836 | S20: =B20/F20 -> 1.8181818
A21: 17 | B21: 21 | C21: =C20+B21 -> 262 | D21: =B21*1.13 -> 23.73 | E21: 0 | F21: 11 | G21: 6 | H21: 16 | I21: =F21+G21 -> 17 | J21: =J20+F21 -> 190 | K21: =(K20+F21)/2 -> 11.944336 | L21: 20 | M21: 0 | N21: 4 | O21: =IF(F21+E21="",0,F21-B21) -> -10 | P21: =B21*7.33 -> 153.93 | Q21: 106.26 | R21: =Q21/P21 -> 0.69031378 | S21: =B21/F21 -> 1.9090909
A22: 18 | B22: 16 | C22: =C21+B22 -> 278 | D22: =B22*1.13 -> 18.08 | E22: 0 | F22: 11 | G22: 6 | H22: 16 | I22: =F22+G22 -> 17 | J22: =J21+F22 -> 201 | K22: =(K21+F22)/2 -> 11.472168 | L22: 20 | M22: 0 | N22: 4 | O22: =IF(F22+E22="",0,F22-B22) -> -5 | P22: =B22*7.33 -> 117.28 | Q22: 97.42 | R22: =Q22/P22 -> 0.83066166 | S22: =B22/F22 -> 1.4545455
A23: 19 | B23: 17 | C23: =C22+B23 -> 295 | D23: =B23*1.13 -> 19.21 | E23: 0 | F23: 11 | G23: 6 | H23: 15 | I23: =F23+G23 -> 17 | J23: =J22+F23 -> 212 | K23: =(K22+F23)/2 -> 11.236084 | L23: 20 | M23: 0 | N23: 4 | O23: =IF(F23+E23="",0,F23-B23) -> -6 | P23: =B23*7.33 -> 124.61 | Q23: 93.51 | R23: =Q23/P23 -> 0.75042131 | S23: =B23/F23 -> 1.5454545
A24: 20 | B24: 13 | C24: =C23+B24 -> 308 | D24: =B24*1.13 -> 14.69 | E24: 0 | F24: 11 | G24: 6 | H24: 9 | I24: =F24+G24 -> 17 | J24: =J23+F24 -> 223 | K24: =(K23+F24)/2 -> 11.118042 | L24: 20 | M24: 3 | N24: 4 | O24: =IF(F24+E24="",0,F24-B24) -> -2 | P24: =B24*7.33 -> 95.29 | Q24: 80.98 | R24: =Q24/P24 -> 0.84982684 | S24: =B24/F24 -> 1.1818182

Sheet Munka1
K3: BC-ből
D4: 202506 | K4: Gépcsoportlista
E5: Létszám | K5: Termelési terv
E6: Gépek | K6: Létszámterv, de melyik???
E7: Kézi
E8: …
E9: Szum
D10: Metaadatok | E10: Munkanapok
E11: Műszakszám (Kézi, Gépi)
E12: Műszakhossz gépi
E13: Műszakhossz kézi
E14: Absense ratio
E15: Kezdő dátum
E16: Bef. Dátum
E17: Desc.

Sheet ADAMI
A1: ADAMI | D1: Difference to the plan | H1: =F27-D27 -> 14
D3: Mennyiség/ Quantity | E3: Óra/ Hours | F3: Gépszám | P3: Munka3
F4: 2 | L4: =C9/3200*8 -> 22.5
B5: Napi Terv / Daily plan | D5: 600 | E5: =D5/(3000*F4/8) -> 0.8 | F5: =E23/D23 -> 1.0015556 | L5: =2*D6*8 -> 240 | M5: =L4/L5 -> 0.09375
C6: Workdays | D6: =Headcount!F7 -> 15
C7: Actual day | D7: =Headcount!F8 -> 15 | F7: Out put daily good | J7: Reject
A8: Munkanap / Workdays | B8: Napi terv / Daily plan | C8: Hátralévő mennyiség | D8: Kumulált terv / Cumulative plan | E8: Kimenet (Kumulált) / Output (cumulative) | F8: Teljes kimenet / Total output | G8: Shift 1 | H8: Shift 2 | I8: Shift 3 | J8: Total (QTY) | K8: Total (Ratio) | L8: Shift 1 (Qty) | M8: Shift 2 (Qty) | N8: Shift 3 (Qty) | O8: High reject item code / reject code | P8: Operating hours | Q8: Available operation hours target | R8: Daily opeation hours plan target | S8: Cél / Target | T8: Hatékonyság (kumulált) / Efficiency (cumulative) | U8: Hatékonyság / Efficiency
A9: =Headcount!A10 -> 2 | B9: =$D$5 -> 600 | C9: =D5*D6 -> 9000 | D9: =D5 -> 600 | E9: =F9 -> 1 | F9: =G9+H9+I9 -> 1 | G9: 1 | H9: 0 | I9: 0 | J9: =L9+M9+N9 -> 0 | K9: =IF(J9=0,0,J9/(J9+F9)) -> 0 | L9: 0 | M9: 0 | N9: 0 | P9: =[1]Munka3!$B5 -> 0 | Q9: 16 | R9: =$E$5 -> 0.8 | S9: 1 | T9: =AVERAGE($U$9:U9) -> #DIV/0! | U9: -
A10: =Headcount!A11 -> 3 | B10: =$D$5 -> 600 | C10: =$C$9-D9 -> 8400 | D10: =$D$5+D9 -> 1200 | E10: =IF(E9=0,0,E9+F10) -> 2 | F10: =G10+H10+I10 -> 1 | G10: 1 | H10: 0 | I10: 0 | J10: =L10+M10+N10 -> 0 | K10: =IF(J10=0,0,J10/(J10+F10)) -> 0 | L10: 0 | M10: 0 | N10: 0 | P10: =[1]Munka3!$B6 -> 0 | Q10: 16 | R10: =$E$5 -> 0.8 | S10: 1 | T10: =AVERAGE($U$9:U10) -> #DIV/0! | U10: -
A11: =Headcount!A12 -> 4 | B11: =$D$5 -> 600 | C11: =$C$9-D10 -> 7800 | D11: =$D$5+D10 -> 1800 | E11: =IF(E10=0,0,E10+F11) -> 3 | F11: =G11+H11+I11 -> 1 | G11: 1 | H11: 0 | I11: 0 | J11: =L11+M11+N11 -> 0 | K11: =IF(J11=0,0,J11/(J11+F11)) -> 0 | L11: 0 | M11: 0 | N11: 0 | P11: =[1]Munka3!$B7 -> 0 | Q11: 16 | R11: =$E$5 -> 0.8 | S11: 1 | T11: =AVERAGE($U$9:U11) -> #DIV/0! | U11: -
A12: =Headcount!A13 -> 5 | B12: =$D$5 -> 600 | C12: =$C$9-D11 -> 7200 | D12: =$D$5+D11 -> 2400 | E12: =IF(E11=0,0,E11+F12) -> 4 | F12: =G12+H12+I12 -> 1 | G12: 1 | H12: 0 | I12: 0 | J12: =L12+M12+N12 -> 0 | K12: =IF(J12=0,0,J12/(J12+F12)) -> 0 | L12: 0 | M12: 0 | N12: 0 | P12: =[1]Munka3!$B8 -> 0 | Q12: 16 | R12: =$E$5 -> 0.8 | S12: 1 | T12: =AVERAGE($U$9:U12) -> #DIV/0! | U12: -
A13: =Headcount!A14 -> 6 | B13: =$D$5 -> 600 | C13: =$C$9-D12 -> 6600 | D13: =$D$5+D12 -> 3000 | E13: =IF(E12=0,0,E12+F13) -> 5 | F13: =G13+H13+I13 -> 1 | G13: 1 | H13: 0 | I13: 0 | J13: =L13+M13+N13 -> 0 | K13: =IF(J13=0,0,J13/(J13+F13)) -> 0 | L13: 0 | M13: 0 | N13: 0 | P13: =[1]Munka3!$B9 -> 0 | Q13: 16 | R13: =$E$5 -> 0.8 | S13: 1 | T13: =AVERAGE($U$9:U13) -> #DIV/0! | U13: -
A14: =Headcount!A15 -> 9 | B14: =$D$5 -> 600 | C14: =$C$9-D13 -> 6000 | D14: =$D$5+D13 -> 3600 | E14: =IF(E13=0,0,E13+F14) -> 6 | F14: =G14+H14+I14 -> 1 | G14: 1 | H14: 0 | I14: 0 | J14: =L14+M14+N14 -> 0 | K14: =IF(J14=0,0,J14/(J14+F14)) -> 0 | L14: 0 | M14: 0 | N14: 0 | P14: =[1]Munka3!$B10 -> 0 | Q14: 16 | R14: =$E$5 -> 0.8 | S14: 1 | T14: =AVERAGE($U$9:U14) -> #DIV/0! | U14: -
A15: =Headcount!A16 -> 10 | B15: =$D$5 -> 600 | C15: =$C$9-D14 -> 5400 | D15: =$D$5+D14 -> 4200 | E15: =IF(E14=0,0,E14+F15) -> 2245 | F15: =G15+H15+I15 -> 2239 | G15: 2239 | H15: 0 | I15: 0 | J15: =L15+M15+N15 -> 0 | K15: =IF(J15=0,0,J15/(J15+F15)) -> 0 | L15: 0 | M15: 0 | N15: 0 | P15: =[1]Munka3!$B11 -> 0 | Q15: 16 | R15: =$E$5 -> 0.8 | S15: 1 | T15: =AVERAGE($U$9:U15) -> 1.0949 | U15: 1.0949
A16: =Headcount!A17 -> 11 | B16: =$D$5 -> 600 | C16: =$C$9-D15 -> 4800 | D16: =$D$5+D15 -> 4800 | E16: =IF(E15=0,0,E15+F16) -> 7758 | F16: =G16+H16+I16 -> 5513 | G16: 5513 | H16: 0 | I16: 0 | J16: =L16+M16+N16 -> 0 | K16: =IF(J16=0,0,J16/(J16+F16)) -> 0 | L16: 0 | M16: 0 | N16: 0 | P16: =[1]Munka3!$B12 -> 0 | Q16: 16 | R16: =$E$5 -> 0.8 | S16: 1 | T16: =AVERAGE($U$9:U16) -> 1.04915 | U16: 1.0034
A17: =Headcount!A18 -> 12 | B17: =$D$5 -> 600 | C17: =$C$9-D16 -> 4200 | D17: =$D$5+D16 -> 5400 | E17: =IF(E16=0,0,E16+F17) -> 9008 | F17: =G17+H17+I17 -> 1250 | G17: 1250 | H17: 0 | I17: 0 | J17: =L17+M17+N17 -> 0 | K17: =IF(J17=0,0,J17/(J17+F17)) -> 0 | L17: 0 | M17: 0 | N17: 0 | P17: =[1]Munka3!$B13 -> 0 | Q17: 16 | R17: =$E$5 -> 0.8 | S17: 1 | T17: =AVERAGE($U$9:U17) -> 1.0359667 | U17: 1.0096
A18: =Headcount!A19 -> 13 | B18: =$D$5 -> 600 | C18: =$C$9-D17 -> 3600 | D18: =$D$5+D17 -> 6000 | E18: =IF(E17=0,0,E17+F18) -> 9009 | F18: =G18+H18+I18 -> 1 | G18: 1 | H18: 0 | I18: 0 | J18: =L18+M18+N18 -> 0 | K18: =IF(J18=0,0,J18/(J18+F18)) -> 0 | L18: 0 | M18: 0 | N18: 0 | P18: =[1]Munka3!$B14 -> 0 | Q18: 16 | R18: =$E$5 -> 0.8 | S18: 1 | T18: =AVERAGE($U$9:U18) -> 1.0359667 | U18: -
A19: =Headcount!A20 -> 16 | B19: =$D$5 -> 600 | C19: =$C$9-D18 -> 3000 | D19: =$D$5+D18 -> 6600 | E19: =IF(E18=0,0,E18+F19) -> 9010 | F19: =G19+H19+I19 -> 1 | G19: 1 | H19: 0 | I19: 0 | J19: =L19+M19+N19 -> 0 | K19: =IF(J19=0,0,J19/(J19+F19)) -> 0 | L19: 0 | M19: 0 | N19: 0 | P19: =[1]Munka3!$B15 -> 0 | Q19: 16 | R19: =$E$5 -> 0.8 | S19: 1 | T19: =AVERAGE($U$9:U19) -> 1.0359667 | U19: -
A20: =Headcount!A21 -> 17 | B20: =$D$5 -> 600 | C20: =$C$9-D19 -> 2400 | D20: =$D$5+D19 -> 7200 | E20: =IF(E19=0,0,E19+F20) -> 9011 | F20: =G20+H20+I20 -> 1 | G20: 1 | H20: 0 | I20: 0 | J20: =L20+M20+N20 -> 0 | K20: =IF(J20=0,0,J20/(J20+F20)) -> 0 | L20: 0 | M20: 0 | N20: 0 | P20: =[1]Munka3!$B16 -> 0 | Q20: 16 | R20: =$E$5 -> 0.8 | S20: 1 | T20: =AVERAGE($U$9:U20) -> 1.0359667 | U20: -
A21: =Headcount!A22 -> 18 | B21: =$D$5 -> 600 | C21: =$C$9-D20 -> 1800 | D21: =$D$5+D20 -> 7800 | E21: =IF(E20=0,0,E20+F21) -> 9012 | F21: =G21+H21+I21 -> 1 | G21: 1 | H21: 0 | I21: 0 | J21: =L21+M21+N21 -> 0 | K21: =IF(J21=0,0,J21/(J21+F21)) -> 0 | L21: 0 | M21: 0 | N21: 0 | P21: =[1]Munka3!$B17 -> 0 | Q21: 16 | R21: =$E$5 -> 0.8 | S21: 1 | T21: =AVERAGE($U$9:U21) -> 1.0359667 | U21: -
A22: =Headcount!A23 -> 19 | B22: =$D$5 -> 600 | C22: =$C$9-D21 -> 1200 | D22: =$D$5+D21 -> 8400 | E22: =IF(E21=0,0,E21+F22) -> 9013 | F22: =G22+H22+I22 -> 1 | G22: 1 | H22: 0 | I22: 0 | J22: =L22+M22+N22 -> 0 | K22: =IF(J22=0,0,J22/(J22+F22)) -> 0 | L22: 0 | M22: 0 | N22: 0 | P22: =[1]Munka3!$B18 -> 0 | Q22: 16 | R22: =$E$5 -> 0.8 | S22: 1 | T22: =AVERAGE($U$9:U22) -> 1.0359667 | U22: -
A23: =Headcount!A24 -> 20 | B23: =$D$5 -> 600 | C23: =$C$9-D22 -> 600 | D23: =$D$5+D22 -> 9000 | E23: =IF(E22=0,0,E22+F23) -> 9014 | F23: =G23+H23+I23 -> 1 | G23: 1 | H23: 0 | I23: 0 | J23: =L23+M23+N23 -> 0 | K23: =IF(J23=0,0,J23/(J23+F23)) -> 0 | L23: 0 | M23: 0 | N23: 0 | P23: =[1]Munka3!$B19 -> 0 | Q23: 16 | R23: =$E$5 -> 0.8 | S23: 1 | T23: =AVERAGE($U$9:U23) -> 1.0359667 | U23: -
A27: Summ Line | D27: =D7*D5 -> 9000 | F27: =SUM(F9:F25) -> 9014 | L27: =SUM(L9:L26) -> 0 | M27: =SUM(M9:M26) -> 0 | N27: =SUM(N9:N26) -> 0 | O27: =SUM(L27:N27) -> 0

Sheet MIM
A1: MIM | D1: Difference to the plan | H1: =F31-D31 -> 0
B5: Napi Terv / Daily plan | D5: 0 | F5: =E9/D9 -> #DIV/0!
C6: Workdays | D6: =Headcount!F7 -> 15
C7: Actual day | D7: =Headcount!F8 -> 15 | F7: Out put daily good | J7: Reject
A8: Munkanap / Workdays | B8: Napi terv / Daily plan | C8: Hátralévő mennyiség | D8: Kumulált terv / Cumulative plan | E8: Kimenet (Kumulált) / Output (cumulative) | F8: Teljes kimenet / Total output | G8: Shift 1 | H8: Shift 2 | I8: Shift 3 | J8: Total (QTY) | K8: Total (Ratio) | L8: Shift 1 (Qty) | M8: Shift 2 (Qty) | N8: Shift 3 (Qty) | O8: High reject item code / reject code | P8: Cél / Target | Q8: Hatékonyság (kumulált) / Efficiency (cumulative) | R8: Hatékonyság / Efficiency
A9: =Headcount!A10 -> 2 | B9: =$D$5 -> 0 | C9: =D5*D6 -> 0 | D9: =D5 -> 0 | E9: =F9 -> 0 | F9: =G9+H9+I9 -> 0 | H9: 0 | I9: 0 | J9: =L9+M9+N9 -> 0 | K9: =IF(J9=0,0,J9/(J9+F9)) -> 0 | M9: 0 | N9: 0 | P9: 1
A10: =Headcount!A11 -> 3 | B10: =$D$5 -> 0 | C10: =$C$9-D9 -> 0 | D10: =$D$5+D9 -> 0 | E10: =IF(E9=0,0,E9+F10) -> 0 | F10: =G10+H10+I10 -> 0 | H10: 0 | I10: 0 | J10: =L10+M10+N10 -> 0 | K10: =IF(J10=0,0,J10/(J10+F10)) -> 0 | M10: 0 | N10: 0 | P10: 1
A11: =Headcount!A12 -> 4 | B11: =$D$5 -> 0 | C11: =$C$9-D10 -> 0 | D11: =$D$5+D10 -> 0 | F11: =G11+H11+I11 -> 0 | H11: 0 | I11: 0 | J11: =L11+M11+N11 -> 0 | K11: =IF(J11=0,0,J11/(J11+F11)) -> 0 | M11: 0 | N11: 0 | P11: 1
A12: =Headcount!A13 -> 5 | B12: =$D$5 -> 0 | C12: =$C$9-D11 -> 0 | D12: =$D$5+D11 -> 0 | F12: =G12+H12+I12 -> 0 | H12: 0 | I12: 0 | J12: =L12+M12+N12 -> 0 | K12: =IF(J12=0,0,J12/(J12+F12)) -> 0 | M12: 0 | N12: 0 | P12: 1
A13: =Headcount!A14 -> 6 | B13: =$D$5 -> 0 | C13: =$C$9-D12 -> 0 | D13: =$D$5+D12 -> 0 | F13: =G13+H13+I13 -> 0 | H13: 0 | I13: 0 | J13: =L13+M13+N13 -> 0 | K13: =IF(J13=0,0,J13/(J13+F13)) -> 0 | M13: 0 | N13: 0 | P13: 1
A14: =Headcount!A15 -> 9 | B14: =$D$5 -> 0 | C14: =$C$9-D13 -> 0 | D14: =$D$5+D13 -> 0 | F14: =G14+H14+I14 -> 0 | H14: 0 | I14: 0 | J14: =L14+M14+N14 -> 0 | K14: =IF(J14=0,0,J14/(J14+F14)) -> 0 | M14: 0 | N14: 0 | P14: 1
A15: =Headcount!A16 -> 10 | B15: =$D$5 -> 0 | C15: =$C$9-D14 -> 0 | D15: =$D$5+D14 -> 0 | F15: =G15+H15+I15 -> 0 | H15: 0 | I15: 0 | J15: =L15+M15+N15 -> 0 | K15: =IF(J15=0,0,J15/(J15+F15)) -> 0 | M15: 0 | N15: 0 | P15: 1
A16: =Headcount!A17 -> 11 | B16: =$D$5 -> 0 | C16: =$C$9-D15 -> 0 | D16: =$D$5+D15 -> 0 | F16: =G16+H16+I16 -> 0 | H16: 0 | I16: 0 | J16: =L16+M16+N16 -> 0 | K16: =IF(J16=0,0,J16/(J16+F16)) -> 0 | M16: 0 | N16: 0 | P16: 1
A17: =Headcount!A18 -> 12 | B17: =$D$5 -> 0 | C17: =$C$9-D16 -> 0 | D17: =$D$5+D16 -> 0 | F17: =G17+H17+I17 -> 0 | H17: 0 | I17: 0 | J17: =L17+M17+N17 -> 0 | K17: =IF(J17=0,0,J17/(J17+F17)) -> 0 | M17: 0 | N17: 0 | P17: 1
A18: =Headcount!A19 -> 13 | B18: =$D$5 -> 0 | C18: =$C$9-D17 -> 0 | D18: =$D$5+D17 -> 0 | F18: =G18+H18+I18 -> 0 | H18: 0 | I18: 0 | J18: =L18+M18+N18 -> 0 | K18: =IF(J18=0,0,J18/(J18+F18)) -> 0 | M18: 0 | N18: 0 | P18: 1
A19: =Headcount!A20 -> 16 | B19: =$D$5 -> 0 | C19: =$C$9-D18 -> 0 | D19: =$D$5+D18 -> 0 | F19: =G19+H19+I19 -> 0 | H19: 0 | I19: 0 | J19: =L19+M19+N19 -> 0 | K19: =IF(J19=0,0,J19/(J19+F19)) -> 0 | M19: 0 | N19: 0 | P19: 1
A20: =Headcount!A21 -> 17 | B20: =$D$5 -> 0 | C20: =$C$9-D19 -> 0 | D20: =$D$5+D19 -> 0 | F20: =G20+H20+I20 -> 0 | H20: 0 | I20: 0 | J20: =L20+M20+N20 -> 0 | K20: =IF(J20=0,0,J20/(J20+F20)) -> 0 | M20: 0 | N20: 0 | P20: 1
A21: =Headcount!A22 -> 18 | B21: =$D$5 -> 0 | C21: =$C$9-D20 -> 0 | D21: =$D$5+D20 -> 0 | F21: =G21+H21+I21 -> 0 | H21: 0 | I21: 0 | J21: =L21+M21+N21 -> 0 | K21: =IF(J21=0,0,J21/(J21+F21)) -> 0 | M21: 0 | N21: 0 | P21: 1
A22: =Headcount!A23 -> 19 | B22: =$D$5 -> 0 | C22: =$C$9-D21 -> 0 | D22: =$D$5+D21 -> 0 | F22: =G22+H22+I22 -> 0 | H22: 0 | I22: 0 | J22: =L22+M22+N22 -> 0 | K22: =IF(J22=0,0,J22/(J22+F22)) -> 0 | M22: 0 | N22: 0 | P22: 1
... A28: =Headcount!A29 -> 0 | B28: =$D$5 -> 0 | C28: =$C$9-D27 -> 0 | D28: =$D$5+D27 -> 0 | F28: =G28+H28+I28 -> 0 | H28: 0 | I28: 0 | J28: =L28+M28+N28 -> 0 | K28: =IF(J28=0,0,J28/(J28+F28)) -> 0 | M28: 0 | N28: 0 | P28: 1
A31: Summ Line | D31: =D7*D5 -> 0 | F31: =SUM(F9:F29) -> 0 | L31: =SUM(L9:L30) -> 0 | M31: =SUM(M9:M30) -> 0 | N31: =SUM(N9:N30) -> 0 | O31: =SUM(L31:N31) -> 0

Sheet CAOI
A1: CAOI | D1: Difference to the plan | H1: =F27-D27 -> 0
D3: Mennyiség/ Quantity | E3: Óra/ Hours
L4: =C9/3200*8 -> 0
B5: Napi Terv / Daily plan | D5: 0 | E5: =D5/(3000/8) -> 0 | F5: =E9/D9 -> #DIV/0! | L5: =1*D6*8 -> 120 | M5: =L4/L5 -> 0
C6: Workdays | D6: =Headcount!F7 -> 15
C7: Actual day | D7: =Headcount!F8 -> 15 | F7: Out put daily good | J7: Reject
A8: Munkanap / Workdays | B8: Napi terv / Daily plan | C8: Hátralévő mennyiség | D8: Kumulált terv / Cumulative plan | E8: Kimenet (Kumulált) / Output (cumulative) | F8: Teljes kimenet / Total output | G8: Shift 1 | H8: Shift 2 | I8: Shift 3 | J8: Total (QTY) | K8: Total (Ratio) | L8: Shift 1 | M8: Shift 2 | N8: Shift 3 | O8: Comment | P8: Operating hours | Q8: Operation hours target | R8: Daily opeation hours plan target | S8: Cél / Target | T8: Hatékonyság (kumulált) / Efficiency (cumulative) | U8: Hatékonyság / Efficiency
A9: =Headcount!A10 -> 2 | B9: =$D$5 -> 0 | C9: =D5*D6 -> 0 | D9: =D5 -> 0 | E9: =F9 -> 0 | F9: =G9+H9+I9 -> 0 | G9: 0 | H9: 0 | I9: 0 | J9: =L9+M9+N9 -> 0 | K9: =IF(J9=0,0,J9/(J9+F9)) -> 0 | L9: 0 | M9: 0 | N9: 0 | P9: =[1]Munka3!$E5 -> 0 | Q9: 8 | R9: =$E$5 -> 0 | S9: 1 | T9: =AVERAGE($U$9:U9) -> #DIV/0! | U9: -
A10: =Headcount!A11 -> 3 | B10: =$D$5 -> 0 | C10: =$C$9-D9 -> 0 | D10: =D9+$D$5 -> 0 | E10: =IF(E9=0,0,E9+F10) -> 0 | F10: =G10+H10+I10 -> 0 | H10: 0 | I10: 0 | J10: =L10+M10+N10 -> 0 | K10: 0 | L10: 0 | M10: 0 | N10: 0 | P10: =[1]Munka3!$E6 -> 0 | Q10: 8 | R10: =$E$5 -> 0 | S10: 1 | T10: =AVERAGE($U$9:U10) -> #DIV/0!
A11: =Headcount!A12 -> 4 | B11: =$D$5 -> 0 | C11: =$C$9-D10 -> 0 | D11: =D10+$D$5 -> 0 | E11: =IF(E10=0,0,E10+F11) -> 0 | F11: =G11+H11+I11 -> 0 | H11: 0 | I11: 0 | J11: =L11+M11+N11 -> 0 | K11: 0 | L11: 0 | M11: 0 | N11: 0 | P11: =[1]Munka3!$E7 -> 0 | Q11: 8 | R11: =$E$5 -> 0 | S11: 1 | T11: =AVERAGE($U$9:U11) -> #DIV/0!
A12: =Headcount!A13 -> 5 | B12: =$D$5 -> 0 | C12: =$C$9-D11 -> 0 | D12: =D11+$D$5 -> 0 | E12: =IF(E11=0,0,E11+F12) -> 0 | F12: =G12+H12+I12 -> 0 | H12: 0 | I12: 0 | J12: =L12+M12+N12 -> 0 | K12: =IF(J12=0,0,J12/(J12+F12)) -> 0 | L12: 0 | M12: 0 | N12: 0 | P12: =[1]Munka3!$E8 -> 0 | Q12: 8 | R12: =$E$5 -> 0 | S12: 1 | T12: =AVERAGE($U$9:U12) -> #DIV/0!
A13: =Headcount!A14 -> 6 | B13: =$D$5 -> 0 | C13: =$C$9-D12 -> 0 | D13: =D12+$D$5 -> 0 | E13: =IF(E12=0,0,E12+F13) -> 0 | F13: =G13+H13+I13 -> 0 | H13: 0 | I13: 0 | J13: =L13+M13+N13 -> 0 | K13: =IF(J13=0,0,J13/(J13+F13)) -> 0 | L13: 0 | M13: 0 | N13: 0 | P13: =[1]Munka3!$E9 -> 0 | Q13: 8 | R13: =$E$5 -> 0 | S13: 1 | T13: =AVERAGE($U$9:U13) -> #DIV/0!
A14: =Headcount!A15 -> 9 | B14: =$D$5 -> 0 | C14: =$C$9-D13 -> 0 | D14: =D13+$D$5 -> 0 | E14: =IF(E13=0,0,E13+F14) -> 0 | F14: =G14+H14+I14 -> 0 | H14: 0 | I14: 0 | J14: =L14+M14+N14 -> 0 | K14: =IF(J14=0,0,J14/(J14+F14)) -> 0 | L14: 0 | M14: 0 | N14: 0 | P14: =[1]Munka3!$E10 -> 0 | Q14: 8 | R14: =$E$5 -> 0 | S14: 1 | T14: =AVERAGE($U$9:U14) -> #DIV/0!
A15: =Headcount!A16 -> 10 | B15: =$D$5 -> 0 | C15: =$C$9-D14 -> 0 | D15: =D14+$D$5 -> 0 | E15: =IF(E14=0,0,E14+F15) -> 0 | F15: =G15+H15+I15 -> 0 | H15: 0 | I15: 0 | J15: =L15+M15+N15 -> 0 | K15: =IF(J15=0,0,J15/(J15+F15)) -> 0 | L15: 0 | M15: 0 | N15: 0 | P15: =[1]Munka3!$E11 -> 0 | Q15: 8 | R15: =$E$5 -> 0 | S15: 1 | T15: =AVERAGE($U$9:U15) -> #DIV/0!
A16: =Headcount!A17 -> 11 | B16: =$D$5 -> 0 | C16: =$C$9-D15 -> 0 | D16: =D15+$D$5 -> 0 | E16: =IF(E15=0,0,E15+F16) -> 0 | F16: =G16+H16+I16 -> 0 | H16: 0 | I16: 0 | J16: =L16+M16+N16 -> 0 | K16: =IF(J16=0,0,J16/(J16+F16)) -> 0 | L16: 0 | M16: 0 | N16: 0 | P16: =[1]Munka3!$E12 -> 0 | Q16: 8 | R16: =$E$5 -> 0 | S16: 1 | T16: =AVERAGE($U$9:U16) -> #DIV/0!
A17: =Headcount!A18 -> 12 | B17: =$D$5 -> 0 | C17: =$C$9-D16 -> 0 | D17: =D16+$D$5 -> 0 | E17: =IF(E16=0,0,E16+F17) -> 0 | F17: =G17+H17+I17 -> 0 | H17: 0 | I17: 0 | J17: =L17+M17+N17 -> 0 | K17: =IF(J17=0,0,J17/(J17+F17)) -> 0 | L17: 0 | M17: 0 | N17: 0 | P17: =[1]Munka3!$E13 -> 0 | Q17: 8 | R17: =$E$5 -> 0 | S17: 1 | T17: =AVERAGE($U$9:U17) -> #DIV/0!
A18: =Headcount!A19 -> 13 | B18: =$D$5 -> 0 | C18: =$C$9-D17 -> 0 | D18: =D17+$D$5 -> 0 | E18: =IF(E17=0,0,E17+F18) -> 0 | F18: =G18+H18+I18 -> 0 | H18: 0 | I18: 0 | J18: =L18+M18+N18 -> 0 | K18: =IF(J18=0,0,J18/(J18+F18)) -> 0 | L18: 0 | M18: 0 | N18: 0 | P18: =[1]Munka3!$E14 -> 0 | Q18: 8 | R18: =$E$5 -> 0 | S18: 1 | T18: =AVERAGE($U$9:U18) -> #DIV/0!
A19: =Headcount!A20 -> 16 | B19: =$D$5 -> 0 | C19: =$C$9-D18 -> 0 | D19: =D18+$D$5 -> 0 | E19: =IF(E18=0,0,E18+F19) -> 0 | F19: =G19+H19+I19 -> 0 | H19: 0 | I19: 0 | J19: =L19+M19+N19 -> 0 | K19: =IF(J19=0,0,J19/(J19+F19)) -> 0 | L19: 0 | M19: 0 | N19: 0 | P19: =[1]Munka3!$E15 -> 0 | Q19: 8 | R19: =$E$5 -> 0 | S19: 1 | T19: =AVERAGE($U$9:U19) -> #DIV/0!
A20: =Headcount!A21 -> 17 | B20: =$D$5 -> 0 | C20: =$C$9-D19 -> 0 | D20: =D19+$D$5 -> 0 | E20: =IF(E19=0,0,E19+F20) -> 0 | F20: =G20+H20+I20 -> 0 | H20: 0 | I20: 0 | J20: =L20+M20+N20 -> 0 | K20: =IF(J20=0,0,J20/(J20+F20)) -> 0 | L20: 0 | M20: 0 | N20: 0 | P20: =[1]Munka3!$E16 -> 0 | Q20: 8 | R20: =$E$5 -> 0 | S20: 1 | T20: =AVERAGE($U$9:U20) -> #DIV/0!
A21: =Headcount!A22 -> 18 | B21: =$D$5 -> 0 | C21: =$C$9-D20 -> 0 | D21: =D20+$D$5 -> 0 | E21: =IF(E20=0,0,E20+F21) -> 0 | F21: =G21+H21+I21 -> 0 | H21: 0 | I21: 0 | J21: =L21+M21+N21 -> 0 | K21: =IF(J21=0,0,J21/(J21+F21)) -> 0 | L21: 0 | M21: 0 | N21: 0 | P21: =[1]Munka3!$E17 -> 0 | Q21: 8 | R21: =$E$5 -> 0 | S21: 1 | T21: =AVERAGE($U$9:U21) -> #DIV/0!
A22: =Headcount!A23 -> 19 | B22: =$D$5 -> 0 | C22: =$C$9-D21 -> 0 | D22: =D21+$D$5 -> 0 | E22: =IF(E21=0,0,E21+F22) -> 0 | F22: =G22+H22+I22 -> 0 | H22: 0 | I22: 0 | J22: =L22+M22+N22 -> 0 | K22: =IF(J22=0,0,J22/(J22+F22)) -> 0 | L22: 0 | M22: 0 | N22: 0 | P22: =[1]Munka3!$E18 -> 0 | Q22: 8 | R22: =$E$5 -> 0 | S22: 1 | T22: =AVERAGE($U$9:U22) -> #DIV/0!
A23: =Headcount!A24 -> 20 | B23: =$D$5 -> 0 | C23: =$C$9-D22 -> 0 | D23: =D22+$D$5 -> 0 | E23: =IF(E22=0,0,E22+F23) -> 0 | F23: =G23+H23+I23 -> 0 | H23: 0 | I23: 0 | J23: =L23+M23+N23 -> 0 | K23: =IF(J23=0,0,J23/(J23+F23)) -> 0 | L23: 0 | M23: 0 | N23: 0 | P23: =[1]Munka3!$E19 -> 0 | Q23: 8 | R23: =$E$5 -> 0 | S23: 1 | T23: =AVERAGE($U$9:U23) -> #DIV/0!
A27: Summ Line | D27: =D7*D5 -> 0 | F27: =SUM(F9:F25) -> 0 | L27: =SUM(L9:L26) -> 0 | M27: =SUM(M9:M26) -> 0 | N27: =SUM(N9:N26) -> 0 | O27: =SUM(L27:N27) -> 0

Sheet AD Auto PKY
A1: ADPKY | D1: Difference to the plan | H1: =F31-D31 -> 1761 | J1: NK: BD-s típus esetén 50mm alatti, valamint AD-s terméknél 60mm alatti I méretű kábelek esetén nem lehet visszahúzni.
D3: Mennyiség/ Quantity | E3: Óra/ Hours | F3: Gépszám
F4: 4 | L4: =C9/4600*8 -> 59.478261
B5: Napi Terv / Daily plan | D5: 2280 | E5: =D5/(4500*F4/8) -> 1.0133333 | F5: =E23/D23 -> 1.0514912 | L5: =4*D6*8 -> 480 | M5: =L4/L5 -> 0.12391304
C6: Workday | D6: =Headcount!F7 -> 15
C7: Actual day | D7: =Headcount!F8 -> 15 | F7: Out put daily good | J7: Reject
A8: Munkanap / Workdays | B8: Napi terv / Daily plan | C8: Hátralévő mennyiség | D8: Kumulált terv / Cumulative plan | E8: Kimenet (Kumulált) / Output (cumulative) | F8: Teljes kimenet / Total output | G8: Shift 1 | H8: Shift 2 | I8: Shift 3 | J8: Total (QTY) | K8: Total (Ratio) | L8: Shift 1 (Qty) | M8: Shift 2 (Qty) | N8: Shift 3 (Qty) | O8: AA hiba (HA ,F S 0374) Beszállítóval fizettetni! | P8: TO Reject | Q8: TST | R8: MAA | S8: Baáll. Selejt | T8: NK | U8: High reject item code / reject code | V8: Operating hours | W8: Available operation hours target | X8: Daily opeation hours plan target | Y8: Cél / Target | Z8: Hatékonyság (kumulált) / Efficiency (cumulative) | AA8: Hatékonyság / Efficiency
A9: =Headcount!A10 -> 2 | B9: =$D$5 -> 2280 | C9: =D5*D6 -> 34200 | D9: =D5 -> 2280 | E9: =F9 -> 1 | F9: =G9+H9+I9 -> 1 | G9: 1 | H9: 0 | I9: 0 | J9: =L9+M9+N9+S9+O9 -> 0 | K9: =IF(J9=0,0,J9/(J9+F9)) -> 0 | L9: 0 | M9: 0 | N9: 0 | O9: 0 | P9: 0 | Q9: 0 | R9: 0 | S9: 0 | T9: 0 | V9: =[1]Munka3!$C5 -> 0 | W9: 32 | X9: =$E$5 -> 1.0133333 | Y9: 1 | Z9: =AVERAGE($AA$9:AA9) -> #DIV/0! | AA9: -
A10: =Headcount!A11 -> 3 | B10: =$D$5 -> 2280 | C10: =$C$9-D9 -> 31920 | D10: =D9+$D$5 -> 4560 | E10: =IF(E9=0,0,E9+F10) -> 2 | F10: =G10+H10+I10 -> 1 | G10: 1 | H10: 0 | I10: 0 | J10: =L10+M10+N10+S10+O10 -> 0 | K10: =IF(J10=0,0,J10/(J10+F10)) -> 0 | L10: 0 | M10: 0 | N10: 0 | O10: 0 | P10: 0 | Q10: 0 | R10: 0 | S10: 0 | T10: 0 | V10: =[1]Munka3!$C6 -> 0 | W10: 32 | X10: =$E$5 -> 1.0133333 | Y10: 1 | Z10: =AVERAGE($AA$9:AA10) -> #DIV/0! | AA10: -
A11: =Headcount!A12 -> 4 | B11: =$D$5 -> 2280 | C11: =$C$9-D10 -> 29640 | D11: =D10+$D$5 -> 6840 | E11: =IF(E10=0,0,E10+F11) -> 8519 | F11: =G11+H11+I11 -> 8517 | G11: 8517 | H11: 0 | I11: 0 | J11: =L11+M11+N11+S11+O11 -> 72 | K11: =IF(J11=0,0,J11/(J11+F11)) -> 0.0083828152 | L11: 42 | M11: 0 | N11: 0 | O11: 0 | P11: 23 | Q11: 0 | R11: 1 | S11: 30 | T11: 10 | U11: - | V11: =[1]Munka3!$C7 -> 0 | W11: 32 | X11: =$E$5 -> 1.0133333 | Y11: 1 | Z11: =AVERAGE($AA$9:AA11) -> 1.0185 | AA11: 1.0185
A12: =Headcount!A13 -> 5 | B12: =$D$5 -> 2280 | C12: =$C$9-D11 -> 27360 | D12: =D11+$D$5 -> 9120 | E12: =IF(E11=0,0,E11+F12) -> 16487 | F12: =G12+H12+I12 -> 7968 | G12: 7968 | H12: 0 | I12: 0 | J12: =L12+M12+N12+S12+O12 -> 18 | K12: =IF(J12=0,0,J12/(J12+F12)) -> 0.0022539444 | L12: 18 | M12: 0 | N12: 0 | O12: 0 | P12: 29 | Q12: 0 | R12: 1 | S12: 0 | T12: 13 | U12: - | V12: =[1]Munka3!$C8 -> 0 | W12: 32 | X12: =$E$5 -> 1.0133333 | Y12: 1 | Z12: =AVERAGE($AA$9:AA12) -> 1.0137 | AA12: 1.0089
A13: =Headcount!A14 -> 6 | B13: =$D$5 -> 2280 | C13: =$C$9-D12 -> 25080 | D13: =D12+$D$5 -> 11400 | E13: =IF(E12=0,0,E12+F13) -> 20075 | F13: =G13+H13+I13 -> 3588 | G13: 3588 | H13: 0 | I13: 0 | J13: =L13+M13+N13+S13+O13 -> 6 | K13: =IF(J13=0,0,J13/(J13+F13)) -> 0.0016694491 | L13: 6 | M13: 0 | N13: 0 | O13: 0 | P13: 13 | Q13: 0 | R13: 0 | S13: 0 | T13: 11 | U13: - | V13: =[1]Munka3!$C9 -> 0 | W13: 32 | X13: =$E$5 -> 1.0133333 | Y13: 1 | Z13: =AVERAGE($AA$9:AA13) -> 1.0412667 | AA13: 1.0964
A14: =Headcount!A15 -> 9 | B14: =$D$5 -> 2280 | C14: =$C$9-D13 -> 22800 | D14: =D13+$D$5 -> 13680 | E14: =IF(E13=0,0,E13+F14) -> 20076 | F14: =G14+H14+I14 -> 1 | G14: 1 | H14: 0 | I14: 0 | J14: =L14+M14+N14+S14+O14 -> 0 | K14: =IF(J14=0,0,J14/(J14+F14)) -> 0 | L14: 0 | M14: 0 | N14: 0 | O14: 0 | P14: 0 | Q14: 0 | R14: 0 | S14: 0 | T14: 0 | U14: - | V14: =[1]Munka3!$C10 -> 0 | W14: 32 | X14: =$E$5 -> 1.0133333 | Y14: 1 | Z14: =AVERAGE($AA$9:AA14) -> 1.0412667 | AA14: -
A15: =Headcount!A16 -> 10 | B15: =$D$5 -> 2280 | C15: =$C$9-D14 -> 20520 | D15: =D14+$D$5 -> 15960 | E15: =IF(E14=0,0,E14+F15) -> 20077 | F15: =G15+H15+I15 -> 1 | G15: 1 | H15: 0 | I15: 0 | J15: =L15+M15+N15+S15+O15 -> 0 | K15: =IF(J15=0,0,J15/(J15+F15)) -> 0 | L15: 0 | M15: 0 | N15: 0 | O15: 0 | P15: 0 | Q15: 0 | R15: 0 | S15: 0 | T15: 0 | U15: - | V15: =[1]Munka3!$C11 -> 0 | W15: 32 | X15: =$E$5 -> 1.0133333 | Y15: 1 | Z15: =AVERAGE($AA$9:AA15) -> 1.0412667 | AA15: -
A16: =Headcount!A17 -> 11 | B16: =$D$5 -> 2280 | C16: =$C$9-D15 -> 18240 | D16: =D15+$D$5 -> 18240 | E16: =IF(E15=0,0,E15+F16) -> 20078 | F16: =G16+H16+I16 -> 1 | G16: 1 | H16: 0 | I16: 0 | J16: =L16+M16+N16+S16+O16 -> 0 | K16: =IF(J16=0,0,J16/(J16+F16)) -> 0 | L16: 0 | M16: 0 | N16: 0 | O16: 0 | P16: 0 | Q16: 0 | R16: 0 | S16: 0 | T16: 0 | U16: - | V16: =[1]Munka3!$C12 -> 0 | W16: 32 | X16: =$E$5 -> 1.0133333 | Y16: 1 | Z16: =AVERAGE($AA$9:AA16) -> 1.0412667 | AA16: -
A17: =Headcount!A18 -> 12 | B17: =$D$5 -> 2280 | C17: =$C$9-D16 -> 15960 | D17: =D16+$D$5 -> 20520 | E17: =IF(E16=0,0,E16+F17) -> 28429 | F17: =G17+H17+I17 -> 8351 | G17: 8351 | H17: 0 | I17: 0 | J17: =L17+M17+N17+S17+O17 -> 38 | K17: =IF(J17=0,0,J17/(J17+F17)) -> 0.0045297413 | L17: 29 | M17: 0 | N17: 0 | O17: 0 | P17: 51 | Q17: 0 | R17: 126 | S17: 9 | T17: 37 | U17: - | V17: =[1]Munka3!$C13 -> 0 | W17: 32 | X17: =$E$5 -> 1.0133333 | Y17: 1 | Z17: =AVERAGE($AA$9:AA17) -> 1.051925 | AA17: 1.0839
A18: =Headcount!A19 -> 13 | B18: =$D$5 -> 2280 | C18: =$C$9-D17 -> 13680 | D18: =D17+$D$5 -> 22800 | E18: =IF(E17=0,0,E17+F18) -> 34256 | F18: =G18+H18+I18 -> 5827 | G18: 5827 | H18: 0 | I18: 0 | J18: =L18+M18+N18+S18+O18 -> 17 | K18: =IF(J18=0,0,J18/(J18+F18)) -> 0.0029089665 | L18: 17 | M18: 0 | N18: 0 | O18: 0 | P18: 30 | Q18: 0 | R18: 36 | S18: 0 | T18: 20 | U18: - | V18: =[1]Munka3!$C14 -> 0 | W18: 32 | X18: =$E$5 -> 1.0133333 | Y18: 1 | Z18: =AVERAGE($AA$9:AA18) -> 1.0482 | AA18: 1.0333
A19: =Headcount!A20 -> 16 | B19: =$D$5 -> 2280 | C19: =$C$9-D18 -> 11400 | D19: =D18+$D$5 -> 25080 | E19: =IF(E18=0,0,E18+F19) -> 34257 | F19: =G19+H19+I19 -> 1 | G19: 1 | H19: 0 | I19: 0 | J19: =L19+M19+N19+S19+O19 -> 0 | K19: =IF(J19=0,0,J19/(J19+F19)) -> 0 | L19: 0 | M19: 0 | N19: 0 | O19: 0 | P19: 0 | Q19: 0 | R19: 0 | S19: 0 | T19: 0 | U19: - | V19: =[1]Munka3!$C15 -> 0 | W19: 32 | X19: =$E$5 -> 1.0133333 | Y19: 1 | Z19: =AVERAGE($AA$9:AA19) -> 1.0482 | AA19: -
A20: =Headcount!A21 -> 17 | B20: =$D$5 -> 2280 | C20: =$C$9-D19 -> 9120 | D20: =D19+$D$5 -> 27360 | E20: =IF(E19=0,0,E19+F20) -> 34258 | F20: =G20+H20+I20 -> 1 | G20: 1 | H20: 0 | I20: 0 | J20: =L20+M20+N20+S20+O20 -> 0 | K20: =IF(J20=0,0,J20/(J20+F20)) -> 0 | L20: 0 | M20: 0 | N20: 0 | O20: 0 | P20: 0 | Q20: 0 | R20: 0 | S20: 0 | T20: 0 | U20: - | V20: =[1]Munka3!$C16 -> 0 | W20: 32 | X20: =$E$5 -> 1.0133333 | Y20: 1 | Z20: =AVERAGE($AA$9:AA20) -> 1.0482 | AA20: -
A21: =Headcount!A22 -> 18 | B21: =$D$5 -> 2280 | C21: =$C$9-D20 -> 6840 | D21: =D20+$D$5 -> 29640 | E21: =IF(E20=0,0,E20+F21) -> 35959 | F21: =G21+H21+I21 -> 1701 | G21: 1701 | H21: 0 | I21: 0 | J21: =L21+M21+N21+S21+O21 -> 17 | K21: =IF(J21=0,0,J21/(J21+F21)) -> 0.009895227 | L21: 7 | M21: 0 | N21: 0 | O21: 0 | P21: 4 | Q21: 0 | R21: 10 | S21: 10 | T21: 5 | U21: - | V21: =[1]Munka3!$C17 -> 0 | W21: 32 | X21: =$E$5 -> 1.0133333 | Y21: 1 | Z21: =AVERAGE($AA$9:AA21) -> 1.0662833 | AA21: 1.1567
A22: =Headcount!A23 -> 19 | B22: =$D$5 -> 2280 | C22: =$C$9-D21 -> 4560 | D22: =D21+$D$5 -> 31920 | E22: =IF(E21=0,0,E21+F22) -> 35960 | F22: =G22+H22+I22 -> 1 | G22: 1 | H22: 0 | I22: 0 | J22: =L22+M22+N22+S22+O22 -> 0 | K22: =IF(J22=0,0,J22/(J22+F22)) -> 0 | L22: 0 | M22: 0 | N22: 0 | O22: 0 | P22: 0 | Q22: 0 | R22: 0 | S22: 0 | T22: 0 | U22: - | V22: =[1]Munka3!$C18 -> 0 | W22: 32 | X22: =$E$5 -> 1.0133333 | Y22: 1 | Z22: =AVERAGE($AA$9:AA22) -> 1.0662833 | AA22: -
A23: =Headcount!A24 -> 20 | B23: =$D$5 -> 2280 | C23: =$C$9-D22 -> 2280 | D23: =D22+$D$5 -> 34200 | E23: =IF(E22=0,0,E22+F23) -> 35961 | F23: =G23+H23+I23 -> 1 | G23: 1 | H23: 0 | I23: 0 | J23: =L23+M23+N23+S23+O23 -> 0 | K23: =IF(J23=0,0,J23/(J23+F23)) -> 0 | L23: 0 | M23: 0 | N23: 0 | O23: 0 | P23: 0 | Q23: 0 | R23: 0 | S23: 0 | T23: 0 | U23: - | V23: =[1]Munka3!$C19 -> 0 | W23: 32 | X23: =$E$5 -> 1.0133333 | Y23: 1 | Z23: =AVERAGE($AA$9:AA23) -> 1.0662833 | AA23: -
A31: Summ line | D31: =D7*D5 -> 34200 | F31: =SUM(F9:F29) -> 35961 | J31: =SUM(J9:J30) -> 168 | K31: =IF(J31=0,0,J31/(J31+F31)) -> 0.0046500042 | L31: =SUM(L9:L30) -> 119 | M31: =SUM(M9:M30) -> 0 | N31: =SUM(N9:N30) -> 0 | O31: =SUM(O9:O30) -> 0 | P31: =SUM(P9:P30) -> 150 | Q31: =SUM(Q9:Q30) -> 0 | R31: =SUM(R9:R30) -> 174 | S31: =SUM(S9:S30) -> 49 | T31: =SUM(T9:T30) -> 96
I33: 185 | L33: Srap with TO/AA | N33: =L31+M31+N31+P31+R31+S31+T31+O31 -> 588
I34: 257 | L34: Srap without TO/AA | N34: =L31+M31+N31+S31+T31 -> 264

Sheet Manual PKY
A1: MAN | C1: Difference to the plan | G1: =E33-C33 -> 0
A2: PKY
B5: Daily plan | C5: 0 | E5: =D18/C18 -> #DIV/0!
B6: Workday | C6: =Headcount!F7 -> 15
B7: Actual day | C7: =Headcount!F8 -> 15 | E7: Out put daily good | I7: Operator / day TTL
A8: Munkanap | B8: Hátralévő mennyiség | C8: Komulált terv | D8: Kimenet (Komulált) | E8: Total | F8: Shift 1 | G8: Shift 2 | H8: Shift 3 | I8: Op.Plan | J8: Op.Act | K8: Diff | L8: Qty/op | M8: Productivity (NAV) | N8: Difficult item's code | P8: Efficiency
A9: =Headcount!A10 -> 2 | B9: =C5*C6 -> 0 | C9: =C5 -> 0 | D9: =E9 -> 0 | E9: =F9+G9+H9 -> 0
A10: =Headcount!A11 -> 3 | B10: =$B$9-C10 -> 0 | C10: =C9+$C$5 -> 0 | D10: =IF(E10=0,0,D9+E10) -> 0 | E10: =F10+G10+H10 -> 0 | L10: =IF(E10=0,0,E10/J10) -> 0
A11: =Headcount!A12 -> 4 | B11: =$B$9-C11 -> 0 | C11: =C10+$C$5 -> 0 | D11: =IF(E11=0,0,D10+E11) -> 0 | E11: =F11+G11+H11 -> 0 | L11: =IF(E11=0,0,E11/J11) -> 0
A12: =Headcount!A13 -> 5 | B12: =$B$10-C11 -> 0 | C12: =C11+$C$5 -> 0 | D12: =IF(E12=0,0,D11+E12) -> 0 | E12: =F12+G12+H12 -> 0 | L12: =IF(E12=0,0,E12/J12) -> 0
A13: =Headcount!A14 -> 6 | B13: =$B$10-C12 -> 0 | C13: =C12+$C$5 -> 0 | D13: =IF(E13=0,0,D12+E13) -> 0 | E13: =F13+G13+H13 -> 0 | L13: =IF(E13=0,0,E13/J13) -> 0
A14: =Headcount!A15 -> 9 | B14: =$B$10-C13 -> 0 | C14: =C13+$C$5 -> 0 | D14: =IF(E14=0,0,D13+E14) -> 0 | E14: =F14+G14+H14 -> 0 | L14: =IF(E14=0,0,E14/J14) -> 0
A15: =Headcount!A16 -> 10 | B15: =$B$10-C14 -> 0 | C15: =C14+$C$5 -> 0 | D15: =IF(E15=0,0,D14+E15) -> 0 | E15: =F15+G15+H15 -> 0 | L15: =IF(E15=0,0,E15/J15) -> 0
A16: =Headcount!A17 -> 11 | B16: =$B$10-C15 -> 0 | C16: =C15+$C$5 -> 0 | D16: =IF(E16=0,0,D15+E16) -> 0 | E16: =F16+G16+H16 -> 0 | L16: =IF(E16=0,0,E16/J16) -> 0
A17: =Headcount!A18 -> 12 | B17: =$B$10-C16 -> 0 | C17: =C16+$C$5 -> 0 | D17: =IF(E17=0,0,D16+E17) -> 0 | E17: =F17+G17+H17 -> 0 | L17: =IF(E17=0,0,E17/J17) -> 0
A18: =Headcount!A19 -> 13 | B18: =$B$10-C17 -> 0 | C18: =C17+$C$5 -> 0 | D18: =IF(E18=0,0,D17+E18) -> 0 | E18: =F18+G18+H18 -> 0 | L18: =IF(E18=0,0,E18/J18) -> 0
A19: =Headcount!A20 -> 16 | B19: =$B$10-C18 -> 0 | C19: =C18+$C$5 -> 0 | D19: =IF(E19=0,0,D18+E19) -> 0 | E19: =F19+G19+H19 -> 0 | L19: =IF(E19=0,0,E19/J19) -> 0
A20: =Headcount!#REF! -> #REF! | B20: =$B$10-C19 -> 0 | C20: =C19+$C$5 -> 0 | D20: =IF(E20=0,0,D19+E20) -> 0 | E20: =F20+G20+H20 -> 0 | L20: =IF(E20=0,0,E20/J20) -> 0
A21: =Headcount!A21 -> 17 | B21: =$B$10-C20 -> 0 | C21: =C20+$C$5 -> 0 | D21: =IF(E21=0,0,D20+E21) -> 0 | E21: =F21+G21+H21 -> 0 | L21: =IF(E21=0,0,E21/J21) -> 0
A22: =Headcount!A22 -> 18 | B22: =$B$10-C21 -> 0 | C22: =C21+$C$5 -> 0 | D22: =IF(E22=0,0,D21+E22) -> 0 | E22: =F22+G22+H22 -> 0 | L22: =IF(E22=0,0,E22/J22) -> 0
A23: =Headcount!A23 -> 19 | B23: =$B$10-C22 -> 0 | C23: =C22+$C$5 -> 0 | D23: =IF(E23=0,0,D22+E23) -> 0 | E23: =F23+G23+H23 -> 0 | L23: =IF(E23=0,0,E23/J23) -> 0
E32: =F32+G32+H32 -> 0
A33: Summ line | C33: =C5*C7 -> 0 | E33: =SUM(E9:E32) -> 0

Sheet CYT
A1: CYT | D1: Difference to the plan | H1: =F31-D31 -> 5910
H2: ='AD Auto PKY'!H1:I1+CYT!H1 -> 7671
C3: Mennyiség/ Quantity | D3: Óra/ Hours | E3: Gépszám
E4: 2 | L4: =C9/4000*8 -> 150
A5: Daily Plan | C5: 5000 | D5: =C5/(4000*E4/8) -> 5 | F5: =E23/D23 -> 1.0788 | L5: =2*C6*8 -> 240 | M5: =L4/L5 -> 0.625
A6: Workday | C6: =Headcount!F7 -> 15
A7: Actual day | C7: =Headcount!F8 -> 15 | F7: Out put daily good | J7: Reject
A8: Munkanap / Workdays | B8: Napi terv / Daily plan | C8: Hátralévő mennyiség | D8: Kumulált terv / Cumulative plan | E8: Kimenet (Kumulált) / Output (cumulative) | F8: Teljes kimenet / Total output | G8: Shift 1 | H8: Shift 2 | I8: Shift 3 | J8: Total (QTY) | K8: Total (Ratio) | L8: Shift 1 (Qty) | M8: Shift 2 (Qty) | N8: Shift 3 (Qty) | O8: Setup reject | P8: AA hiba (HA ,F) Beszállítóval fizettetni! | Q8: TO | R8: MAA | S8: TST | T8: NK | U8: High reject item code / reject code | V8: Operating hours | W8: Available operation hours target | X8: Daily opeation hours plan target | Y8: Cél / Target | Z8: Hatékonyság (kumulált) / Efficiency (cumulative) | AA8: Hatékonyság / Efficiency
A9: =Headcount!A10 -> 2 | B9: =$C$5 -> 5000 | C9: =C5*C6 -> 75000 | D9: =C5 -> 5000 | E9: =F9 -> 6059 | F9: =G9+H9+I9 -> 6059 | G9: 6059 | H9: 0 | I9: 0 | J9: =L9+M9+N9+O9+P9 -> 189 | K9: =IF(J9=0,0,J9/(J9+F9)) -> 0.03024968 | L9: 166 | M9: 0 | N9: 0 | O9: 23 | P9: 0 | Q9: 9 | R9: 23 | S9: 0 | T9: 25 | U9: 12-1368 Elüti az S és MA méretet, sebbesség 5-re levéve. MA 70 db / S 20 db /E 20 db / BS 23 db | V9: =[1]Munka3!$G5 -> 8 | W9: =8*2 -> 16 | X9: =$D$5 -> 5 | Y9: 1 | Z9: =AVERAGE($AA$9:AA9) -> 0.8881 | AA9: 0.8881 | AB9: 12-1368
A10: =Headcount!A11 -> 3 | B10: =$C$5 -> 5000 | C10: =$C$9-D9 -> 70000 | D10: =D9+$C$5 -> 10000 | E10: =IF(E9=0,0,E9+F10) -> 11902 | F10: =G10+H10+I10 -> 5843 | G10: 5843 | H10: 0 | I10: 0 | J10: =L10+M10+N10+O10+P10 -> 164 | K10: =IF(J10=0,0,J10/(J10+F10)) -> 0.027301482 | L10: 144 | M10: 0 | N10: 0 | O10: 20 | P10: 0 | Q10: 16 | R10: 15 | S10: 0 | T10: 14 | U10: 1200-1368 MA 45 db / E 62 db / BS 11 db | V10: =[1]Munka3!$G6 -> 0 | W10: =8*2 -> 16 | X10: =$D$5 -> 5 | Y10: 1 | Z10: =AVERAGE($AA$9:AA10) -> 0.9316 | AA10: 0.9751 | AB10: 12-1368
A11: =Headcount!A12 -> 4 | B11: =$C$5 -> 5000 | C11: =$C$9-D10 -> 65000 | D11: =D10+$C$5 -> 15000 | E11: =IF(E10=0,0,E10+F11) -> 17485 | F11: =G11+H11+I11 -> 5583 | G11: 5583 | H11: 0 | I11: 0 | J11: =L11+M11+N11+O11+P11 -> 81 | K11: =IF(J11=0,0,J11/(J11+F11)) -> 0.014300847 | L11: 74 | M11: 0 | N11: 0 | O11: 7 | P11: 0 | Q11: 10 | R11: 166 | S11: 0 | T11: 7 | U11: 12-1323 MA 17 db 1201-1294 MA 13 db | V11: =[1]Munka3!$G7 -> 0 | W11: =8*2 -> 16 | X11: =$D$5 -> 5 | Y11: 1 | Z11: =AVERAGE($AA$9:AA11) -> 0.96383333 | AA11: 1.0283
A12: =Headcount!A13 -> 5 | B12: =$C$5 -> 5000 | C12: =$C$9-D11 -> 60000 | D12: =D11+$C$5 -> 20000 | E12: =IF(E11=0,0,E11+F12) -> 22823 | F12: =G12+H12+I12 -> 5338 | G12: 5338 | H12: 0 | I12: 0 | J12: =L12+M12+N12+O12+P12 -> 112 | K12: =IF(J12=0,0,J12/(J12+F12)) -> 0.020550459 | L12: 103 | M12: 0 | N12: 0 | O12: 9 | P12: 0 | Q12: 8 | R12: 138 | S12: 0 | T12: 19 | U12: 12-1368 J 23 db / SK 22 db / E 12 db / NK 14 db | V12: =[1]Munka3!$G8 -> 0 | W12: =8*2 -> 16 | X12: =$D$5 -> 5 | Y12: 1 | Z12: =AVERAGE($AA$9:AA12) -> 0.970575 | AA12: 0.9908 | AB12: 12-1368 88%
A13: =Headcount!A14 -> 6 | B13: =$C$5 -> 5000 | C13: =$C$9-D12 -> 55000 | D13: =D12+$C$5 -> 25000 | E13: =IF(E12=0,0,E12+F13) -> 29179 | F13: =G13+H13+I13 -> 6356 | G13: 6356 | H13: 0 | I13: 0 | J13: =L13+M13+N13+O13+P13 -> 85 | K13: =IF(J13=0,0,J13/(J13+F13)) -> 0.013196709 | L13: 85 | M13: 0 | N13: 0 | O13: 0 | P13: 0 | Q13: 15 | R13: 207 | S13: 0 | T13: 50 | U13: 12-1368 NK 45 db / J 34 db / E 10 db | V13: =[1]Munka3!$G9 -> 0 | W13: =8*2 -> 16 | X13: =$D$5 -> 5 | Y13: 1 | Z13: =AVERAGE($AA$9:AA13) -> 1.02584 | AA13: 1.2469
A14: =Headcount!A15 -> 9 | B14: =$C$5 -> 5000 | C14: =$C$9-D13 -> 50000 | D14: =D13+$C$5 -> 30000 | E14: =IF(E13=0,0,E13+F14) -> 34464 | F14: =G14+H14+I14 -> 5285 | G14: 5285 | H14: 0 | I14: 0 | J14: =L14+M14+N14+O14+P14 -> 97 | K14: =IF(J14=0,0,J14/(J14+F14)) -> 0.01802304 | L14: 75 | M14: 0 | N14: 0 | O14: 22 | P14: 0 | Q14: 13 | R14: 93 | S14: 0 | T14: 9 | U14: 12-1217 BS 7 db (kis db szám mellé) 12-1337 BS 15 db 12-1413 E 14 db | V14: =[1]Munka3!$G10 -> 0 | W14: =8*2 -> 16 | X14: =$D$5 -> 5 | Y14: 1 | Z14: =AVERAGE($AA$9:AA14) -> 1.0111333 | AA14: 0.9376 | AB14: 12-1217 44% (kis db szám 160 db)
A15: =Headcount!A16 -> 10 | B15: =$C$5 -> 5000 | C15: =$C$9-D14 -> 45000 | D15: =D14+$C$5 -> 35000 | E15: =IF(E14=0,0,E14+F15) -> 42376 | F15: =G15+H15+I15 -> 7912 | G15: 7912 | H15: 0 | I15: 0 | J15: =L15+M15+N15+O15+P15 -> 44 | K15: =IF(J15=0,0,J15/(J15+F15)) -> 0.0055304173 | L15: 31 | M15: 0 | N15: 0 | O15: 13 | P15: 0 | Q15: 12 | R15: 344 | S15: 0 | T15: 12 | U15: 12-1233 BS 13 db | V15: =[1]Munka3!$G11 -> 0 | W15: =8*2 -> 16 | X15: =$D$5 -> 5 | Y15: 1 | Z15: =AVERAGE($AA$9:AA15) -> 1.0186714 | AA15: 1.0639
A16: =Headcount!A17 -> 11 | B16: =$C$5 -> 5000 | C16: =$C$9-D15 -> 40000 | D16: =D15+$C$5 -> 40000 | E16: =IF(E15=0,0,E15+F16) -> 50128 | F16: =G16+H16+I16 -> 7752 | G16: 7752 | H16: 0 | I16: 0 | J16: =L16+M16+N16+O16+P16 -> 57 | K16: =IF(J16=0,0,J16/(J16+F16)) -> 0.0072992701 | L16: 57 | M16: 0 | N16: 0 | O16: 0 | P16: 0 | Q16: 51 | R16: 121 | S16: 0 | T16: 18 | U16: 12-1233 E 16 db | V16: =[1]Munka3!$G12 -> 0 | W16: =8*2 -> 16 | X16: =$D$5 -> 5 | Y16: 1 | Z16: =AVERAGE($AA$9:AA16) -> 1.014775 | AA16: 0.9875
A17: =Headcount!A18 -> 12 | B17: =$C$5 -> 5000 | C17: =$C$9-D16 -> 35000 | D17: =D16+$C$5 -> 45000 | E17: =IF(E16=0,0,E16+F17) -> 55914 | F17: =G17+H17+I17 -> 5786 | G17: 5786 | H17: 0 | I17: 0 | J17: =L17+M17+N17+O17+P17 -> 48 | K17: =IF(J17=0,0,J17/(J17+F17)) -> 0.0082276311 | L17: 45 | M17: 0 | N17: 0 | O17: 3 | P17: 0 | Q17: 153 | R17: 18 | S17: 0 | T17: 9 | U17: - | V17: =[1]Munka3!$G13 -> 0 | W17: =8*2 -> 16 | X17: =$D$5 -> 5 | Y17: 1 | Z17: =AVERAGE($AA$9:AA17) -> 1.0108222 | AA17: 0.9792
A18: =Headcount!A19 -> 13 | B18: =$C$5 -> 5000 | C18: =$C$9-D17 -> 30000 | D18: =D17+$C$5 -> 50000 | E18: =IF(E17=0,0,E17+F18) -> 62286 | F18: =G18+H18+I18 -> 6372 | G18: 6372 | H18: 0 | I18: 0 | J18: =L18+M18+N18+O18+P18 -> 82 | K18: =IF(J18=0,0,J18/(J18+F18)) -> 0.012705299 | L18: 61 | M18: 0 | N18: 0 | O18: 21 | P18: 0 | Q18: 142 | R18: 29 | S18: 0 | T18: 17 | U18: - | V18: =[1]Munka3!$G14 -> 0 | W18: =8*2 -> 16 | X18: =$D$5 -> 5 | Y18: 1 | Z18: =AVERAGE($AA$9:AA18) -> 1.00679 | AA18: 0.9705
A19: =Headcount!A20 -> 16 | B19: =$C$5 -> 5000 | C19: =$C$9-D18 -> 25000 | D19: =D18+$C$5 -> 55000 | E19: =IF(E18=0,0,E18+F19) -> 64007 | F19: =G19+H19+I19 -> 1721 | G19: 1721 | H19: 0 | I19: 0 | J19: =L19+M19+N19+O19+P19 -> 19 | K19: =IF(J19=0,0,J19/(J19+F19)) -> 0.01091954 | L19: 19 | M19: 0 | N19: 0 | O19: 0 | P19: 0 | Q19: 19 | R19: 29 | S19: 0 | T19: 3 | U19: - | V19: =[1]Munka3!$G15 -> 0 | W19: =8*2 -> 16 | X19: =$D$5 -> 5 | Y19: 1 | Z19: =AVERAGE($AA$9:AA19) -> 1.0057545 | AA19: 0.9954
A20: =Headcount!A21 -> 17 | B20: =$C$5 -> 5000 | C20: =$C$9-D19 -> 20000 | D20: =D19+$C$5 -> 60000 | E20: =IF(E19=0,0,E19+F20) -> 64008 | F20: =G20+H20+I20 -> 1 | G20: 1 | H20: 0 | I20: 0 | J20: =L20+M20+N20+O20+P20 -> 0 | K20: =IF(J20=0,0,J20/(J20+F20)) -> 0 | L20: 0 | M20: 0 | N20: 0 | O20: 0 | P20: 0 | Q20: 0 | R20: 0 | S20: 0 | T20: 0 | U20: - | V20: =[1]Munka3!$G16 -> 0 | W20: =8*2 -> 16 | X20: =$D$5 -> 5 | Y20: 1 | Z20: =AVERAGE($AA$9:AA20) -> 1.0057545 | AA20: -
A21: =Headcount!A22 -> 18 | B21: =$C$5 -> 5000 | C21: =$C$9-D20 -> 15000 | D21: =D20+$C$5 -> 65000 | E21: =IF(E20=0,0,E20+F21) -> 69757 | F21: =G21+H21+I21 -> 5749 | G21: 5749 | H21: 0 | I21: 0 | J21: =L21+M21+N21+O21+P21 -> 73 | K21: =IF(J21=0,0,J21/(J21+F21)) -> 0.012538647 | L21: 55 | M21: 0 | N21: 0 | O21: 18 | P21: 0 | Q21: 56 | R21: 2 | S21: 0 | T21: 5 | U21: 1200-1367 BS 14 db / MA 20 db | V21: =[1]Munka3!$G17 -> 0 | W21: =8*2 -> 16 | X21: =$D$5 -> 5 | Y21: 1 | Z21: =AVERAGE($AA$9:AA21) -> 1.0098083 | AA21: 1.0544
A22: =Headcount!A23 -> 19 | B22: =$C$5 -> 5000 | C22: =$C$9-D21 -> 10000 | D22: =D21+$C$5 -> 70000 | E22: =IF(E21=0,0,E21+F22) -> 76238 | F22: =G22+H22+I22 -> 6481 | G22: 6481 | H22: 0 | I22: 0 | J22: =L22+M22+N22+O22+P22 -> 30 | K22: =IF(J22=0,0,J22/(J22+F22)) -> 0.0046075872 | L22: 24 | M22: 0 | N22: 0 | O22: 6 | P22: 0 | Q22: 199 | R22: 8 | S22: 0 | T22: 6 | U22: - | V22: =[1]Munka3!$G18 -> 0 | W22: 16 | X22: =$D$5 -> 5 | Y22: 1 | Z22: =AVERAGE($AA$9:AA22) -> 1.0073538 | AA22: 0.9779
A23: =Headcount!A24 -> 20 | B23: =$C$5 -> 5000 | C23: =$C$9-D22 -> 5000 | D23: =D22+$C$5 -> 75000 | E23: =IF(E22=0,0,E22+F23) -> 80910 | F23: =G23+H23+I23 -> 4672 | G23: 4672 | H23: 0 | I23: 0 | J23: =L23+M23+N23+O23+P23 -> 34 | K23: =IF(J23=0,0,J23/(J23+F23)) -> 0.0072248194 | L23: 27 | M23: 0 | N23: 0 | O23: 7 | P23: 0 | Q23: 7 | R23: 26 | S23: 0 | T23: 6 | U23: - | V23: =[1]Munka3!$G19 -> 0 | W23: 16 | X23: =$D$5 -> 5 | Y23: 1 | Z23: =AVERAGE($AA$9:AA23) -> 1.0032286 | AA23: 0.9496
A31: Summ line | D31: =C7*C5 -> 75000 | F31: =SUM(F9:F29) -> 80910 | L31: =SUM(L9:L30) -> 966 | M31: =SUM(M9:M30) -> 0 | N31: =SUM(N9:N30) -> 0 | O31: =SUM(O9:O30) -> 149 | P31: =SUM(P9:P30) -> 0 | Q31: =SUM(Q9:Q30) -> 710 | R31: =SUM(R9:R30) -> 1219 | S31: =SUM(S9:S30) -> 0 | T31: =SUM(T9:T30) -> 200
L33: Scrap with TO/AA | N33: =L31+M31+N31+O31+Q31+R31+T31+P31 -> 3244
L34: Scrap without TO/AA | N34: =L31+M31+N31+O31+T31 -> 1315

Sheet Auto Bending
A1: Auto | C1: Difference to the plan | G1: =E31-C31 -> 0
A2: Bend
B5: Daily plan | C5: 0 | E5: =D9/C9 -> #DIV/0!
B6: Workday | C6: =Headcount!F7 -> 15
B7: Actual day | C7: =Headcount!F8 -> 15 | E7: Out put daily good | I7: Reject
A8: Munkanap | B8: Hátralévő mennyiség | C8: Komulált terv | D8: Kimenet (Komulált) | E8: Total | F8: Shift 1 | G8: Shift 2 | H8: Shift 3 | I8: Total (QTY) | J8: Total (Ratio) | K8: Shift 1 (Qty) | L8: Shift 2 (Qty) | M8: Shift 3 (Qty) | N8: High reject item code / reject code | O8: Efficiency
A9: =Headcount!A10 -> 2 | B9: =C5*C6 -> 0 | C9: =C5 -> 0 | D9: =E9 -> 0 | E9: =F9+G9+H9 -> 0 | G9: 0 | H9: 0 | I9: =K9+L9+M9 -> 0 | J9: =IF(I9=0,0,I9/(I9+E9)) -> 0 | L9: 0 | M9: 0
A10: =Headcount!A11 -> 3 | B10: =B9-$C$5 -> 0 | C10: =C9+$C$5 -> 0 | D10: =IF(E10=0,0,D9+E10) -> 0 | E10: =F10+G10+H10 -> 0 | G10: 0 | H10: 0 | I10: =K10+L10+M10 -> 0 | J10: =IF(I10=0,0,I10/(I10+E10)) -> 0 | L10: 0 | M10: 0
A11: =Headcount!A12 -> 4 | B11: =B10-$C$5 -> 0 | C11: =C10+$C$5 -> 0 | E11: =F11+G11+H11 -> 0 | G11: 0 | H11: 0 | I11: =K11+L11+M11 -> 0 | J11: =IF(I11=0,0,I11/(I11+E11)) -> 0 | L11: 0 | M11: 0
A12: =Headcount!A13 -> 5 | B12: =B11-$C$5 -> 0 | C12: =C11+$C$5 -> 0 | E12: =F12+G12+H12 -> 0 | G12: 0 | H12: 0 | I12: =K12+L12+M12 -> 0 | J12: =IF(I12=0,0,I12/(I12+E12)) -> 0 | L12: 0 | M12: 0
A13: =Headcount!A14 -> 6 | B13: =B12-$C$5 -> 0 | C13: =C12+$C$5 -> 0 | E13: =F13+G13+H13 -> 0 | G13: 0 | H13: 0 | I13: =K13+L13+M13 -> 0 | J13: =IF(I13=0,0,I13/(I13+E13)) -> 0 | L13: 0 | M13: 0
A14: =Headcount!A15 -> 9 | B14: =B13-$C$5 -> 0 | C14: =C13+$C$5 -> 0 | E14: =F14+G14+H14 -> 0 | G14: 0 | H14: 0 | I14: =K14+L14+M14 -> 0 | J14: 0 | L14: 0 | M14: 0
A15: =Headcount!A16 -> 10 | B15: =B14-$C$5 -> 0 | C15: =C14+$C$5 -> 0 | E15: =F15+G15+H15 -> 0 | G15: 0 | H15: 0 | I15: =K15+L15+M15 -> 0 | J15: =IF(I15=0,0,I15/(I15+E15)) -> 0 | L15: 0 | M15: 0
A16: =Headcount!A17 -> 11 | B16: =B15-$C$5 -> 0 | C16: =C15+$C$5 -> 0 | E16: =F16+G16+H16 -> 0 | G16: 0 | H16: 0 | I16: =K16+L16+M16 -> 0 | J16: =IF(I16=0,0,I16/(I16+E16)) -> 0 | L16: 0 | M16: 0
A17: =Headcount!A18 -> 12 | B17: =B16-$C$5 -> 0 | C17: =C16+$C$5 -> 0 | E17: =F17+G17+H17 -> 0 | G17: 0 | H17: 0 | I17: =K17+L17+M17 -> 0 | J17: =IF(I17=0,0,I17/(I17+E17)) -> 0 | L17: 0 | M17: 0
A18: =Headcount!A19 -> 13 | B18: =B17-$C$5 -> 0 | C18: =C17+$C$5 -> 0 | E18: =F18+G18+H18 -> 0 | G18: 0 | H18: 0 | I18: =K18+L18+M18 -> 0 | J18: =IF(I18=0,0,I18/(I18+E18)) -> 0 | L18: 0 | M18: 0
A19: =Headcount!A20 -> 16 | B19: =B18-$C$5 -> 0 | C19: =C18+$C$5 -> 0 | E19: =F19+G19+H19 -> 0 | G19: 0 | H19: 0 | I19: =K19+L19+M19 -> 0 | J19: =IF(I19=0,0,I19/(I19+E19)) -> 0 | L19: 0 | M19: 0
A20: =Headcount!A21 -> 17 | B20: =B19-$C$5 -> 0 | C20: =C19+$C$5 -> 0 | E20: =F20+G20+H20 -> 0 | G20: 0 | H20: 0 | I20: =K20+L20+M20 -> 0 | J20: =IF(I20=0,0,I20/(I20+E20)) -> 0 | L20: 0 | M20: 0
A21: =Headcount!A22 -> 18 | B21: =B20-$C$5 -> 0 | C21: =C20+$C$5 -> 0 | E21: =F21+G21+H21 -> 0 | G21: 0 | H21: 0 | I21: =K21+L21+M21 -> 0 | J21: =IF(I21=0,0,I21/(I21+E21)) -> 0 | L21: 0 | M21: 0
A22: =Headcount!A23 -> 19 | B22: =B21-$C$5 -> 0 | C22: =C21+$C$5 -> 0 | E22: =F22+G22+H22 -> 0 | G22: 0 | H22: 0 | I22: =K22+L22+M22 -> 0 | J22: =IF(I22=0,0,I22/(I22+E22)) -> 0 | L22: 0 | M22: 0
A23: =Headcount!A24 -> 20 | B23: =B22-$C$5 -> 0 | C23: =C22+$C$5 -> 0 | E23: =F23+G23+H23 -> 0 | G23: 0 | H23: 0 | I23: =K23+L23+M23 -> 0 | J23: =IF(I23=0,0,I23/(I23+E23)) -> 0 | L23: 0 | M23: 0
A24: =Headcount!A25 -> 0 | B24: =B23-$C$5 -> 0 | C24: =C23+$C$5 -> 0 | E24: =F24+G24+H24 -> 0 | G24: 0 | H24: 0 | I24: =K24+L24+M24 -> 0 | J24: =IF(I24=0,0,I24/(I24+E24)) -> 0 | L24: 0 | M24: 0
A25: =Headcount!A26 -> 0 | B25: =B24-$C$5 -> 0 | C25: =C24+$C$5 -> 0 | E25: =F25+G25+H25 -> 0 | G25: 0 | H25: 0 | I25: =K25+L25+M25 -> 0 | J25: =IF(I25=0,0,I25/(I25+E25)) -> 0 | L25: 0 | M25: 0
A26: =Headcount!A27 -> 0 | B26: =B25-$C$5 -> 0 | C26: =C25+$C$5 -> 0 | E26: =F26+G26+H26 -> 0 | G26: 0 | H26: 0 | I26: =K26+L26+M26 -> 0 | J26: =IF(I26=0,0,I26/(I26+E26)) -> 0 | L26: 0 | M26: 0
... A28: =Headcount!A29 -> 0 | B28: =B27-$C$5 -> 0 | C28: =C27+$C$5 -> 0 | E28: =F28+G28+H28 -> 0 | G28: 0 | H28: 0 | I28: =K28+L28+M28 -> 0 | J28: =IF(I28=0,0,I28/(I28+E28)) -> 0 | L28: 0 | M28: 0
A31: Summ line | C31: =C7*C5 -> 0 | E31: =SUM(E9:E29) -> 0 | K31: =SUM(K9:K30) -> 0 | L31: =SUM(L9:L30) -> 0 | M31: =SUM(M9:M30) -> 0 | N31: =SUM(K31:M31) -> 0

Sheet SS Auto Bending
A1: SS Auto | D1: Difference to the plan | H1: =F32-D32 -> 54.05
A2: Bend
M4: =C9/2000*8 -> 24.7998
C5: Daily plan | D5: 413.33 | E5: =D5/(2000/8) -> 1.65332 | F5: =E23/D23 -> 1.0087178 | M5: =1*D6*8 -> 120 | N5: =M4/M5 -> 0.206665
C6: Workday | D6: =Headcount!F7 -> 15
C7: Actual day | D7: =Headcount!F8 -> 15 | F7: Out put daily good | J7: Reject
A8: Munkanap | B8: Napi terv / Daily plan | C8: Hátralévő mennyiség | D8: Komulált terv | E8: Kimenet (Komulált) | F8: Total | G8: Shift 1 | H8: Shift 2 | I8: Shift 3 | J8: Total (QTY) | K8: Total (Ratio) | L8: Shift 1 (Qty) | M8: Shift 2 (Qty) | N8: Shift 3 (Qty) | O8: High reject item code / reject code | P8: Operating hours | Q8: Operation hours target | R8: Daily opeation hours plan target | S8: Cél / Target | T8: Hatékonyság (kumulált) / Efficiency (cumulative) | U8: Efficiency
A9: =Headcount!A10 -> 2 | B9: =$D$5 -> 413.33 | C9: =D5*D6 -> 6199.95 | D9: =D5 -> 413.33 | E9: =F9 -> 1 | F9: =G9+H9+I9 -> 1 | G9: 1 | H9: 0 | I9: 0 | J9: =L9+M9+N9 -> 0 | K9: =IF(J9=0,0,J9/(J9+F9)) -> 0 | L9: 0 | M9: 0 | N9: 0 | P9: =[1]Munka3!$H5 -> 0 | Q9: 8 | R9: =$E$5 -> 1.65332 | S9: 1 | T9: =AVERAGE(U$9:$U9) -> #DIV/0! | U9: -
A10: =Headcount!A11 -> 3 | B10: =$D$5 -> 413.33 | C10: =C9-$D$5 -> 5786.62 | D10: =D9+$D$5 -> 826.66 | E10: =IF(F10=0,0,E9+F10) -> 2 | F10: =G10+H10+I10 -> 1 | G10: 1 | H10: 0 | I10: 0 | J10: =L10+M10+N10 -> 0 | K10: =IF(J10=0,0,J10/(J10+F10)) -> 0 | L10: 0 | M10: 0 | N10: 0 | P10: =[1]Munka3!$H6 -> 0 | Q10: 8 | R10: =$E$5 -> 1.65332 | S10: 1 | T10: =AVERAGE(U$9:$U10) -> #DIV/0! | U10: -
A11: =Headcount!A12 -> 4 | B11: =$D$5 -> 413.33 | C11: =C10-$D$5 -> 5373.29 | D11: =D10+$D$5 -> 1239.99 | E11: =IF(F11=0,0,E10+F11) -> 15 | F11: =G11+H11+I11 -> 13 | G11: 13 | H11: 0 | I11: 0 | J11: =L11+M11+N11 -> 9 | K11: =IF(J11=0,0,J11/(J11+F11)) -> 0.40909091 | L11: 9 | M11: 0 | N11: 0 | O11: Program készítésből adódó selejt. | P11: =[1]Munka3!$H7 -> 0 | Q11: 8 | R11: =$E$5 -> 1.65332 | S11: 1 | T11: =AVERAGE(U$9:$U11) -> 1.0737 | U11: 1.0737
A12: =Headcount!A13 -> 5 | B12: =$D$5 -> 413.33 | C12: =C11-$D$5 -> 4959.96 | D12: =D11+$D$5 -> 1653.32 | E12: =IF(F12=0,0,E11+F12) -> 1237 | F12: =G12+H12+I12 -> 1222 | G12: 1222 | H12: 0 | I12: 0 | J12: =L12+M12+N12 -> 2 | K12: =IF(J12=0,0,J12/(J12+F12)) -> 0.0016339869 | L12: 2 | M12: 0 | N12: 0 | P12: =[1]Munka3!$H8 -> 0 | Q12: 8 | R12: =$E$5 -> 1.65332 | S12: 1 | T12: =AVERAGE(U$9:$U12) -> 1.07735 | U12: 1.081
A13: =Headcount!A14 -> 6 | B13: =$D$5 -> 413.33 | C13: =C12-$D$5 -> 4546.63 | D13: =D12+$D$5 -> 2066.65 | E13: =IF(F13=0,0,E12+F13) -> 2073 | F13: =G13+H13+I13 -> 836 | G13: 836 | H13: 0 | I13: 0 | J13: =L13+M13+N13 -> 13 | K13: =IF(J13=0,0,J13/(J13+F13)) -> 0.015312132 | L13: 13 | M13: 0 | N13: 0 | P13: =[1]Munka3!$H9 -> 0 | Q13: 8 | R13: =$E$5 -> 1.65332 | S13: 1 | T13: =AVERAGE(U$9:$U13) -> 1.0148 | U13: 0.8897
A14: =Headcount!A15 -> 9 | B14: =$D$5 -> 413.33 | C14: =C13-$D$5 -> 4133.3 | D14: =D13+$D$5 -> 2479.98 | E14: =IF(F14=0,0,E13+F14) -> 3583 | F14: =G14+H14+I14 -> 1510 | G14: 1510 | H14: 0 | I14: 0 | J14: =L14+M14+N14 -> 16 | K14: =IF(J14=0,0,J14/(J14+F14)) -> 0.010484928 | L14: 16 | M14: 0 | N14: 0 | P14: =[1]Munka3!$H10 -> 0 | Q14: 8 | R14: =$E$5 -> 1.65332 | S14: 1 | T14: =AVERAGE(U$9:$U14) -> 0.9654 | U14: 0.8172
A15: =Headcount!A16 -> 10 | B15: =$D$5 -> 413.33 | C15: =C14-$D$5 -> 3719.97 | D15: =D14+$D$5 -> 2893.31 | E15: =IF(F15=0,0,E14+F15) -> 4948 | F15: =G15+H15+I15 -> 1365 | G15: 1365 | H15: 0 | I15: 0 | J15: =L15+M15+N15 -> 7 | K15: =IF(J15=0,0,J15/(J15+F15)) -> 0.0051020408 | L15: 7 | M15: 0 | N15: 0 | P15: =[1]Munka3!$H11 -> 0 | Q15: 8 | R15: =$E$5 -> 1.65332 | S15: 1 | T15: =AVERAGE(U$9:$U15) -> 0.9319 | U15: 0.7979
A16: =Headcount!A17 -> 11 | B16: =$D$5 -> 413.33 | C16: =C15-$D$5 -> 3306.64 | D16: =D15+$D$5 -> 3306.64 | E16: =IF(F16=0,0,E15+F16) -> 5017 | F16: =G16+H16+I16 -> 69 | G16: 69 | H16: 0 | I16: 0 | J16: =L16+M16+N16 -> 0 | K16: =IF(J16=0,0,J16/(J16+F16)) -> 0 | L16: 0 | M16: 0 | N16: 0 | P16: =[1]Munka3!$H12 -> 0 | Q16: 8 | R16: =$E$5 -> 1.65332 | S16: 1 | T16: =AVERAGE(U$9:$U16) -> 0.9319 | U16: -
A17: =Headcount!A18 -> 12 | B17: =$D$5 -> 413.33 | C17: =C16-$D$5 -> 2893.31 | D17: =D16+$D$5 -> 3719.97 | E17: =IF(F17=0,0,E16+F17) -> 5018 | F17: =G17+H17+I17 -> 1 | G17: 1 | H17: 0 | I17: 0 | J17: =L17+M17+N17 -> 0 | K17: =IF(J17=0,0,J17/(J17+F17)) -> 0 | L17: 0 | M17: 0 | N17: 0 | P17: =[1]Munka3!$H13 -> 0 | Q17: 8 | R17: =$E$5 -> 1.65332 | S17: 1 | T17: =AVERAGE(U$9:$U17) -> 0.9319 | U17: -
A18: =Headcount!A19 -> 13 | B18: =$D$5 -> 413.33 | C18: =C17-$D$5 -> 2479.98 | D18: =D17+$D$5 -> 4133.3 | E18: =IF(F18=0,0,E17+F18) -> 5019 | F18: =G18+H18+I18 -> 1 | G18: 1 | H18: 0 | I18: 0 | J18: =L18+M18+N18 -> 0 | K18: =IF(J18=0,0,J18/(J18+F18)) -> 0 | L18: 0 | M18: 0 | N18: 0 | P18: =[1]Munka3!$H14 -> 0 | Q18: 8 | R18: =$E$5 -> 1.65332 | S18: 1 | T18: =AVERAGE(U$9:$U18) -> 0.9319 | U18: -
A19: =Headcount!A20 -> 16 | B19: =$D$5 -> 413.33 | C19: =C18-$D$5 -> 2066.65 | D19: =D18+$D$5 -> 4546.63 | E19: =IF(F19=0,0,E18+F19) -> 5867 | F19: =G19+H19+I19 -> 848 | G19: 848 | H19: 0 | I19: 0 | J19: =L19+M19+N19 -> 7 | K19: =IF(J19=0,0,J19/(J19+F19)) -> 0.0081871345 | L19: 7 | M19: 0 | N19: 0 | P19: =[1]Munka3!$H15 -> 0 | Q19: 8 | R19: =$E$5 -> 1.65332 | S19: 1 | T19: =AVERAGE(U$9:$U19) -> 0.91306667 | U19: 0.8189
A20: =Headcount!A21 -> 17 | B20: =$D$5 -> 413.33 | C20: =C19-$D$5 -> 1653.32 | D20: =D19+$D$5 -> 4959.96 | E20: =IF(F20=0,0,E19+F20) -> 6251 | F20: =G20+H20+I20 -> 384 | G20: 384 | H20: 0 | I20: 0 | J20: =L20+M20+N20 -> 0 | K20: =IF(J20=0,0,J20/(J20+F20)) -> 0 | L20: 0 | M20: 0 | N20: 0 | P20: =[1]Munka3!$H16 -> 0 | Q20: 8 | R20: =$E$5 -> 1.65332 | S20: 1 | T20: =AVERAGE(U$9:$U20) -> 0.93731429 | U20: 1.0828
A21: =Headcount!A22 -> 18 | B21: =$D$5 -> 413.33 | C21: =C20-$D$5 -> 1239.99 | D21: =D20+$D$5 -> 5373.29 | E21: =IF(F21=0,0,E20+F21) -> 6252 | F21: =G21+H21+I21 -> 1 | G21: 1 | H21: 0 | I21: 0 | J21: =L21+M21+N21 -> 0 | K21: =IF(J21=0,0,J21/(J21+F21)) -> 0 | L21: 0 | M21: 0 | N21: 0 | P21: =[1]Munka3!$H17 -> 0 | Q21: 8 | R21: =$E$5 -> 1.65332 | S21: 1 | T21: =AVERAGE(U$9:$U21) -> 0.93731429 | U21: -
A22: =Headcount!A23 -> 19 | B22: =$D$5 -> 413.33 | C22: =C21-$D$5 -> 826.66 | D22: =D21+$D$5 -> 5786.62 | E22: =IF(F22=0,0,E21+F22) -> 6253 | F22: =G22+H22+I22 -> 1 | G22: 1 | H22: 0 | I22: 0 | J22: =L22+M22+N22 -> 0 | K22: =IF(J22=0,0,J22/(J22+F22)) -> 0 | L22: 0 | M22: 0 | N22: 0 | P22: =[1]Munka3!$H18 -> 0 | Q22: 8 | R22: =$E$5 -> 1.65332 | S22: 1 | T22: =AVERAGE(U$9:$U22) -> 0.93731429 | U22: -
A23: =Headcount!A24 -> 20 | B23: =$D$5 -> 413.33 | C23: =C22-$D$5 -> 413.33 | D23: =D22+$D$5 -> 6199.95 | E23: =IF(F23=0,0,E22+F23) -> 6254 | F23: =G23+H23+I23 -> 1 | G23: 1 | H23: 0 | I23: 0 | J23: =L23+M23+N23 -> 0 | K23: =IF(J23=0,0,J23/(J23+F23)) -> 0 | L23: 0 | M23: 0 | N23: 0 | P23: =[1]Munka3!$H19 -> 0 | Q23: 8 | R23: =$E$5 -> 1.65332 | S23: 1 | T23: =AVERAGE(U$9:$U23) -> 0.93731429 | U23: -
A32: Summ line | D32: =D7*D5 -> 6199.95 | F32: =SUM(F9:F31) -> 6254 | L32: =SUM(L9:L31) -> 54 | M32: =SUM(M9:M31) -> 0 | N32: =SUM(N9:N31) -> 0 | O32: =SUM(L32:N32) -> 54 | U32: =AVERAGE(U9:U31) -> 0.93731429

Sheet APIM
A1: APIM | D1: Difference to the plan | H1: =F31-D31 -> 108 | J1: Items transfer from coil in-jet to APIM
D3: Mennyiség/ Quantity | E3: Óra/ Hours | F3: Gépszám
F4: 2 | L4: =C9/2200*8 -> 48
C5: Daily plan | D5: 880 | E5: =D5/(2000*F4/8) -> 1.76 | F5: =E21/D21 -> 1.1631119 | L5: =2*D6*8 -> 240 | M5: =L4/L5 -> 0.2
C6: Workday | D6: =Headcount!F7 -> 15
C7: Actual day | D7: =Headcount!F8 -> 15 | F7: Out put daily good | J7: Reject
A8: Munkanap / Workdays | B8: Napi terv / Daily plan | C8: Hátralévő mennyiség | D8: Kumulált terv / Cumulative plan | E8: Kimenet (Kumulált) / Output (cumulative) | F8: Teljes kimenet / Total output | G8: Shift 1 | H8: Shift 2 | I8: Shift 3 | J8: Total (QTY) | K8: Total (Ratio) | L8: Shift 1 (Qty) | M8: Shift 2 (Qty) | N8: Shift 3 (Qty) | O8: Operating hours | P8: Operation hours target | Q8: Daily opeation hours plan target | R8: Cél / Target | S8: Hatékonyság (kumulált) / Efficiency (cumulative) | T8: Hatékonyság / Efficiency
A9: =Headcount!A10 -> 2 | B9: =$D$5 -> 880 | C9: =D5*D6 -> 13200 | D9: =D5 -> 880 | E9: =F9 -> 1 | F9: =G9+H9+I9 -> 1 | G9: 1 | H9: 0 | I9: 0 | J9: =L9+M9+N9 -> 0 | K9: =IF(J9=0,0,J9/(J9+F9)) -> 0 | L9: 0 | M9: 0 | N9: 0 | O9: =[1]Munka3!$D5 -> 6 | P9: =8*2 -> 16 | Q9: =$E$5 -> 1.76 | R9: 1 | S9: =AVERAGE($T$9:T9) -> #DIV/0! | T9: -
A10: =Headcount!A11 -> 3 | B10: =$D$5 -> 880 | C10: =$C$9-D9 -> 12320 | D10: =D9+$D$5 -> 1760 | E10: =IF(E9=0,0,E9+F10) -> 2 | F10: =G10+H10+I10 -> 1 | G10: 1 | H10: 0 | I10: 0 | J10: =L10+M10+N10 -> 0 | K10: =IF(J10=0,0,J10/(J10+F10)) -> 0 | L10: 0 | M10: 0 | N10: 0 | O10: =[1]Munka3!$D6 -> 0 | P10: =8*2 -> 16 | Q10: =$E$5 -> 1.76 | R10: 1 | S10: =AVERAGE($T$9:T10) -> #DIV/0! | T10: -
A11: =Headcount!A12 -> 4 | B11: =$D$5 -> 880 | C11: =$C$9-D10 -> 11440 | D11: =D10+$D$5 -> 2640 | E11: =IF(E10=0,0,E10+F11) -> 1782 | F11: =G11+H11+I11 -> 1780 | G11: 1780 | H11: 0 | I11: 0 | J11: =L11+M11+N11 -> 2 | K11: =IF(J11=0,0,J11/(J11+F11)) -> 0.0011223345 | L11: 2 | M11: 0 | N11: 0 | O11: =[1]Munka3!$D7 -> 0 | P11: =8*2 -> 16 | Q11: =$E$5 -> 1.76 | R11: 1 | S11: =AVERAGE($T$9:T11) -> 0.6688 | T11: 0.6688
